Workbook

Sheet README
A1: Fund model: capital calls, distributions, NAV, IRR, DPI / RVPI / TVPI, LP statement
A2: Synthetic $100mm growth fund, 40 quarters. Illustrative only - no real fund or investor data.
A4: Sheet map | B4: Inputs (commitments, terms, NAV loan, as-of date) -> Fund (quarterly engine incl. loan schedule and a no-loan shadow case) -> Returns (metrics + chart) -> NAV Loan (with vs without comparison) -> LP Statement (per-investor capital account) -> Checks.
A5: Colour code | B5: Blue = input | Black = formula | Green = link from another sheet | Yellow = key assumption or selector.
A6: Capital calls | B6: During the 5-year investment period, calls each quarter = investment + management fee + fund expenses. Investments are 85% of commitments spread evenly.
A7: Distributions & NAV | B7: Portfolio grows at the gross return; a rising share of it is realised each quarter from the first exit quarter, and the rest is liquidated in quarter 40. Investor NAV = portfolio value less accrued carry.
A8: NAV loan extension | B8: A single draw against portfolio value (advance rate x portfolio value, capped) in the chosen quarter. Interest is paid in cash each quarter, exit proceeds sweep the balance down, the net draw is paid out as a special distribution, and investor NAV is net of the loan. Switch it off on Inputs!B35; the NAV Loan sheet always shows both cases.
A9: Metrics | B9: DPI = distributions / paid-in. RVPI = residual NAV / paid-in. TVPI = DPI + RVPI. XIRR uses dated quarter-end flows, with NAV as the terminal value at the as-of date.
A10: Simplifications | B10: (1) Carry is 20% of profit after return of paid-in capital - no preferred return, catch-up or clawback. (2) All investors pro rata, GP commitment included. (3) No fund-level cash or recycling; the only leverage is the optional NAV loan (single draw, no covenants, fixed rate). (4) Flows at quarter-end. (5) Fees post-investment period are netted from distributions.
A12: Key outputs (live)
A13: As-of date | B13: =Returns!B4 -> 47118
A14: Paid-in capital ($mm) | B14: =Returns!B10 -> 95.75
A15: Distributions ($mm) | B15: =Returns!B13 -> 76.27013
A16: Residual NAV ($mm) | B16: =Returns!B14 -> 55.735487
A17: DPI | B17: =Returns!B15 -> 0.79655488
A18: RVPI | B18: =Returns!B16 -> 0.58209386
A19: TVPI | B19: =Returns!B17 -> 1.3786487
A20: Net IRR | B20: =Returns!B18 -> 0.11199238
A21: Gross IRR | B21: =Returns!B26 -> 0.17975699
A22: NAV loan on? (1 = yes) | B22: =Inputs!B35 -> 1
A23: TVPI without loan | B23: ='NAV Loan'!C14 -> 1.3863319
A24: Net IRR without loan | B24: ='NAV Loan'!C15 -> 0.11151399
A25: Model integrity | B25: =Checks!B21 -> ALL CHECKS PASS

Sheet Inputs
A1: Fund model - Inputs
A2: SYNTHETIC illustrative fund. Blue = input, black = formula, green = cross-sheet link, yellow = key assumption. US$ millions.
A4: Fund name | B4: Sample Growth Fund I, L.P. (synthetic)
A5: Units | B5: US$ millions
A8: Investor commitments | B8: Commitment ($mm) | C8: % of fund
A9: LP A (institutional) | B9: 40 | C9: =B9/$B$13 -> 0.4 | D9: Names are synthetic. All investors are treated pro rata to commitment, including the GP commitment (no fee/carry waiver modelled).
A10: LP B (family office) | B10: 30 | C10: =B10/$B$13 -> 0.3
A11: LP C (fund of funds) | B11: 25 | C11: =B11/$B$13 -> 0.25
A12: GP commitment | B12: 5 | C12: =B12/$B$13 -> 0.05
A13: Total commitments | B13: =SUM(B9:B12) -> 100 | C13: =SUM(C9:C12) -> 1
A16: Fund terms | B16: Value
A17: First quarter-end date | B17: 45016 | D17: Quarter 1 ends on this date. Model runs 40 quarters (10 years).
A18: Investment period (quarters) | B18: 20 | D18: 5 years. Calls fund investments, fees and expenses during this period only.
A19: Investable capital, % of commitments | B19: 0.85 | D19: Deployed evenly across the investment period; the balance covers fees and expenses.
A20: Management fee - investment period (% of commitments p.a.) | B20: 0.02 | D20: Charged quarterly (1/4 of annual rate) on total commitments.
A21: Management fee - after investment period (% of opening NAV p.a.) | B21: 0.015 | D21: Netted from distributions once calls stop.
A22: Fund expenses (% of commitments p.a.) | B22: 0.0015 | D22: Audit, admin, legal. Same funding rule as the fee.
A23: Carried interest | B23: 0.2 | D23: Simplified: 20% of profit once cumulative distributions exceed paid-in capital. No preferred return or catch-up (see README).
A24: Gross portfolio return (% p.a.) | B24: 0.18 | D24: Applied quarterly to opening portfolio value; new investments are made at quarter-end.
A25: First exit quarter | B25: 17 | D25: Exits begin in year 5, overlapping the end of the investment period.
A26: Exit rate in first exit quarter (% of portfolio value) | B26: 0.04 | D26: Share of portfolio value realised that quarter.
A27: Exit rate step-up per quarter | B27: 0.015 | D27: Exit rate rises each quarter (capped at 100%). Any remainder is liquidated in the final quarter.
A30: Reporting selection | B30: Value
A31: As-of date for returns metrics (choose a quarter-end) | B31: 47118 | D31: Drop-down. DPI / RVPI / TVPI / IRR on the Returns sheet are measured at this date. Set to 31-Dec-2032 for since-inception, fund-end results.
A34: NAV loan facility (extension) | B34: Value
A35: NAV loan switch (1 = on, 0 = off) | B35: 1 | D35: Off reproduces the original no-loan model exactly. The NAV Loan sheet compares both cases side by side either way.
A36: Draw quarter (quarter number, single draw) | B36: 21 | D36: Default = first quarter after the investment period, once capital calls have stopped.
A37: Advance rate / LTV (% of portfolio value at draw) | B37: 0.15 | D37: Lender advances this share of the closing portfolio value at the draw quarter-end.
A38: Maximum facility size ($mm) | B38: 15 | D38: Cap on the draw: draw = MIN(advance rate x portfolio value, cap).
A39: Interest rate (% p.a., cash-pay quarterly) | B39: 0.09 | D39: Illustrative assumption: NAV facilities are priced at a premium to senior credit. Charged on the opening balance.
A40: Upfront arrangement fee (% of draw) | B40: 0.01 | D40: Deducted from the cash paid out to investors.
A41: Cash sweep: % of exit proceeds applied to repayment | B41: 0.25 | D41: Applied after interest (and post-investment-period fees). Any balance left is repaid in the final quarter.
D42: Use of proceeds: the net draw (draw less arrangement fee) is paid to investors as a special distribution, i.e. a dividend recap. It counts towards carry like any other distribution.

Sheet Fund
A1: Fund cash flows, carry and NAV (quarterly)
A2: US$ millions, flows at quarter-end. Row 6 is the opening balance. Investors are pooled; per-investor figures on the LP Statement sheet are pro rata.
D3: Mechanics: calls = investments + fees + expenses (investment period). After it, fees/expenses are netted from proceeds. Carry = 20% x max(0, cumulative distributions - paid-in). NAV shown net of carry that would be due on a hypothetical liquidation. NAV loan (cols AE-AL) is drawn once, pays cash interest, is swept from exit proceeds, and its net proceeds are distributed; investor NAV is net of the loan balance. Cols AM-AW re-run the fund with no loan for comparison.
A5: Qtr | B5: Quarter end | C5: Inv. period? (1/0) | D5: Opening portfolio value | E5: Investments | F5: Portfolio gain | G5: Exit rate | H5: Gross exit proceeds | I5: Closing portfolio value | J5: Management fee | K5: Fund expenses | L5: Capital calls | M5: Distributions before carry | N5: Carry paid | O5: Net distributions to investors | P5: Cumulative calls (paid-in) | Q5: Cumulative distributions before carry | R5: Cumulative carry paid | S5: Accrued carry (unrealised) | T5: Investor NAV (net of accrued carry) | U5: Cumulative net distributions | V5: DPI | W5: RVPI | X5: TVPI | Y5: Net investor cash flow | Z5: Net flow for XIRR (to as-of, incl. NAV) | AA5: Gross fund cash flow | AB5: Gross flow for XIRR (to as-of, incl. NAV) | AC5: Unfunded commitment | AD5: Carried interest expense (paid + change in accrual) | AE5: NAV loan: opening balance | AF5: NAV loan: draw | AG5: NAV loan: arrangement fee | AH5: NAV loan: interest (cash) | AI5: NAV loan: repayment | AJ5: NAV loan: closing balance | AK5: NAV loan: net cash distributed at draw | AL5: Loan-to-value (loan / portfolio value) | AM5: No-loan case: distributions before carry | AN5: No-loan: cumulative distributions before carry | AO5: No-loan: carry paid | AP5: No-loan: cumulative carry paid | AQ5: No-loan: net distributions | AR5: No-loan: accrued carry | AS5: No-loan: investor NAV | AT5: No-loan: cumulative net distributions | AU5: No-loan: net investor cash flow | AV5: No-loan: net flow for XIRR (to as-of) | AW5: TVPI (no-loan case)
A6: 0 | B6: =EOMONTH(Inputs!$B$17,-3) -> 44926 | C6: opening | I6: 0 | P6: 0 | Q6: 0 | R6: 0 | S6: 0 | T6: 0 | U6: 0 | AJ6: 0 | AN6: 0 | AP6: 0 | AS6: 0 | AT6: 0
A7: =A6+1 -> 1 | B7: =EOMONTH(Inputs!$B$17,3*(A7-1)) -> 45016 | C7: =IF(A7<=Inputs!$B$18,1,0) -> 1 | D7: =I6 -> 0 | E7: =IF(C7=1,Inputs!$B$19*Inputs!$B$13/Inputs!$B$18,0) -> 4.25 | F7: =D7*((1+Inputs!$B$24)^(1/4)-1) -> 0 | G7: =IF(A7=MAX($A$7:$A$46),1,IF(A7<Inputs!$B$25,0,MIN(1,Inputs!$B$26+Inputs!$B$27*(A7-Inputs!$B$25)))) -> 0 | H7: =G7*(D7+E7+F7) -> 0 | I7: =D7+E7+F7-H7 -> 4.25 | J7: =IF(C7=1,Inputs!$B$20*Inputs!$B$13/4,Inputs!$B$21*D7/4) -> 0.5 | K7: =Inputs!$B$22*Inputs!$B$13/4 -> 0.0375 | L7: =IF(C7=1,MIN(E7+J7+K7,Inputs!$B$13-P6),0) -> 4.7875 | M7: =MAX(0,IF(C7=1,H7,H7-J7-K7)-AH7-AI7+AK7) -> 0 | N7: =MAX(0,Inputs!$B$23*MAX(0,Q7-P7)-R6) -> 0 | O7: =M7-N7 -> 0 | P7: =P6+L7 -> 4.7875 | Q7: =Q6+M7 -> 0 | R7: =R6+N7 -> 0 | S7: =MAX(0,Inputs!$B$23*MAX(0,Q7+I7-AJ7-P7)-R7) -> 0 | T7: =I7-AJ7-S7 -> 4.25 | U7: =U6+O7 -> 0 | V7: =IF(P7>0,U7/P7,0) -> 0 | W7: =IF(P7>0,T7/P7,0) -> 0.88772846 | X7: =V7+W7 -> 0.88772846 | Y7: =-L7+O7 -> -4.7875 | Z7: =IF(B7<Inputs!$B$31,Y7,IF(B7=Inputs!$B$31,Y7+T7,0)) -> -4.7875 | AA7: =-E7+H7 -> -4.25 | AB7: =IF(B7<Inputs!$B$31,AA7,IF(B7=Inputs!$B$31,AA7+I7,0)) -> -4.25 | AC7: =Inputs!$B$13-P7 -> 95.2125 | AD7: =N7+S7-S6 -> 0 | AE7: =AJ6 -> 0 | AF7: =IF(AND(Inputs!$B$35=1,A7=Inputs!$B$36),MIN(Inputs!$B$37*I7,Inputs!$B$38),0) -> 0 | AG7: =Inputs!$B$40*AF7 -> 0 | AH7: =Inputs!$B$39/4*AE7 -> 0 | AI7: =IF(A7=MAX($A$7:$A$46),AE7,MIN(AE7,Inputs!$B$41*MAX(0,IF(C7=1,H7,H7-J7-K7)-AH7))) -> 0 | AJ7: =AE7+AF7-AI7 -> 0 | AK7: =AF7-AG7 -> 0 | AL7: =IF(I7>0,AJ7/I7,0) -> 0 | AM7: =IF(C7=1,H7,MAX(0,H7-J7-K7)) -> 0 | AN7: =AN6+AM7 -> 0 | AO7: =MAX(0,Inputs!$B$23*MAX(0,AN7-P7)-AP6) -> 0 | AP7: =AP6+AO7 -> 0 | AQ7: =AM7-AO7 -> 0 | AR7: =MAX(0,Inputs!$B$23*MAX(0,AN7+I7-P7)-AP7) -> 0 | AS7: =I7-AR7 -> 4.25 | AT7: =AT6+AQ7 -> 0 | AU7: =-L7+AQ7 -> -4.7875 | AV7: =IF(B7<Inputs!$B$31,AU7,IF(B7=Inputs!$B$31,AU7+AS7,0)) -> -4.7875 | AW7: =IF(P7>0,(AT7+AS7)/P7,0) -> 0.88772846
A8: =A7+1 -> 2 | B8: =EOMONTH(Inputs!$B$17,3*(A8-1)) -> 45107 | C8: =IF(A8<=Inputs!$B$18,1,0) -> 1 | D8: =I7 -> 4.25 | E8: =IF(C8=1,Inputs!$B$19*Inputs!$B$13/Inputs!$B$18,0) -> 4.25 | F8: =D8*((1+Inputs!$B$24)^(1/4)-1) -> 0.1795482 | G8: =IF(A8=MAX($A$7:$A$46),1,IF(A8<Inputs!$B$25,0,MIN(1,Inputs!$B$26+Inputs!$B$27*(A8-Inputs!$B$25)))) -> 0 | H8: =G8*(D8+E8+F8) -> 0 | I8: =D8+E8+F8-H8 -> 8.6795482 | J8: =IF(C8=1,Inputs!$B$20*Inputs!$B$13/4,Inputs!$B$21*D8/4) -> 0.5 | K8: =Inputs!$B$22*Inputs!$B$13/4 -> 0.0375 | L8: =IF(C8=1,MIN(E8+J8+K8,Inputs!$B$13-P7),0) -> 4.7875 | M8: =MAX(0,IF(C8=1,H8,H8-J8-K8)-AH8-AI8+AK8) -> 0 | N8: =MAX(0,Inputs!$B$23*MAX(0,Q8-P8)-R7) -> 0 | O8: =M8-N8 -> 0 | P8: =P7+L8 -> 9.575 | Q8: =Q7+M8 -> 0 | R8: =R7+N8 -> 0 | S8: =MAX(0,Inputs!$B$23*MAX(0,Q8+I8-AJ8-P8)-R8) -> 0 | T8: =I8-AJ8-S8 -> 8.6795482 | U8: =U7+O8 -> 0 | V8: =IF(P8>0,U8/P8,0) -> 0 | W8: =IF(P8>0,T8/P8,0) -> 0.90648023 | X8: =V8+W8 -> 0.90648023 | Y8: =-L8+O8 -> -4.7875 | Z8: =IF(B8<Inputs!$B$31,Y8,IF(B8=Inputs!$B$31,Y8+T8,0)) -> -4.7875 | AA8: =-E8+H8 -> -4.25 | AB8: =IF(B8<Inputs!$B$31,AA8,IF(B8=Inputs!$B$31,AA8+I8,0)) -> -4.25 | AC8: =Inputs!$B$13-P8 -> 90.425 | AD8: =N8+S8-S7 -> 0 | AE8: =AJ7 -> 0 | AF8: =IF(AND(Inputs!$B$35=1,A8=Inputs!$B$36),MIN(Inputs!$B$37*I8,Inputs!$B$38),0) -> 0 | AG8: =Inputs!$B$40*AF8 -> 0 | AH8: =Inputs!$B$39/4*AE8 -> 0 | AI8: =IF(A8=MAX($A$7:$A$46),AE8,MIN(AE8,Inputs!$B$41*MAX(0,IF(C8=1,H8,H8-J8-K8)-AH8))) -> 0 | AJ8: =AE8+AF8-AI8 -> 0 | AK8: =AF8-AG8 -> 0 | AL8: =IF(I8>0,AJ8/I8,0) -> 0 | AM8: =IF(C8=1,H8,MAX(0,H8-J8-K8)) -> 0 | AN8: =AN7+AM8 -> 0 | AO8: =MAX(0,Inputs!$B$23*MAX(0,AN8-P8)-AP7) -> 0 | AP8: =AP7+AO8 -> 0 | AQ8: =AM8-AO8 -> 0 | AR8: =MAX(0,Inputs!$B$23*MAX(0,AN8+I8-P8)-AP8) -> 0 | AS8: =I8-AR8 -> 8.6795482 | AT8: =AT7+AQ8 -> 0 | AU8: =-L8+AQ8 -> -4.7875 | AV8: =IF(B8<Inputs!$B$31,AU8,IF(B8=Inputs!$B$31,AU8+AS8,0)) -> -4.7875 | AW8: =IF(P8>0,(AT8+AS8)/P8,0) -> 0.90648023
A9: =A8+1 -> 3 | B9: =EOMONTH(Inputs!$B$17,3*(A9-1)) -> 45199 | C9: =IF(A9<=Inputs!$B$18,1,0) -> 1 | D9: =I8 -> 8.6795482 | E9: =IF(C9=1,Inputs!$B$19*Inputs!$B$13/Inputs!$B$18,0) -> 4.25 | F9: =D9*((1+Inputs!$B$24)^(1/4)-1) -> 0.36668171 | G9: =IF(A9=MAX($A$7:$A$46),1,IF(A9<Inputs!$B$25,0,MIN(1,Inputs!$B$26+Inputs!$B$27*(A9-Inputs!$B$25)))) -> 0 | H9: =G9*(D9+E9+F9) -> 0 | I9: =D9+E9+F9-H9 -> 13.29623 | J9: =IF(C9=1,Inputs!$B$20*Inputs!$B$13/4,Inputs!$B$21*D9/4) -> 0.5 | K9: =Inputs!$B$22*Inputs!$B$13/4 -> 0.0375 | L9: =IF(C9=1,MIN(E9+J9+K9,Inputs!$B$13-P8),0) -> 4.7875 | M9: =MAX(0,IF(C9=1,H9,H9-J9-K9)-AH9-AI9+AK9) -> 0 | N9: =MAX(0,Inputs!$B$23*MAX(0,Q9-P9)-R8) -> 0 | O9: =M9-N9 -> 0 | P9: =P8+L9 -> 14.3625 | Q9: =Q8+M9 -> 0 | R9: =R8+N9 -> 0 | S9: =MAX(0,Inputs!$B$23*MAX(0,Q9+I9-AJ9-P9)-R9) -> 0 | T9: =I9-AJ9-S9 -> 13.29623 | U9: =U8+O9 -> 0 | V9: =IF(P9>0,U9/P9,0) -> 0 | W9: =IF(P9>0,T9/P9,0) -> 0.92576013 | X9: =V9+W9 -> 0.92576013 | Y9: =-L9+O9 -> -4.7875 | Z9: =IF(B9<Inputs!$B$31,Y9,IF(B9=Inputs!$B$31,Y9+T9,0)) -> -4.7875 | AA9: =-E9+H9 -> -4.25 | AB9: =IF(B9<Inputs!$B$31,AA9,IF(B9=Inputs!$B$31,AA9+I9,0)) -> -4.25 | AC9: =Inputs!$B$13-P9 -> 85.6375 | AD9: =N9+S9-S8 -> 0 | AE9: =AJ8 -> 0 | AF9: =IF(AND(Inputs!$B$35=1,A9=Inputs!$B$36),MIN(Inputs!$B$37*I9,Inputs!$B$38),0) -> 0 | AG9: =Inputs!$B$40*AF9 -> 0 | AH9: =Inputs!$B$39/4*AE9 -> 0 | AI9: =IF(A9=MAX($A$7:$A$46),AE9,MIN(AE9,Inputs!$B$41*MAX(0,IF(C9=1,H9,H9-J9-K9)-AH9))) -> 0 | AJ9: =AE9+AF9-AI9 -> 0 | AK9: =AF9-AG9 -> 0 | AL9: =IF(I9>0,AJ9/I9,0) -> 0 | AM9: =IF(C9=1,H9,MAX(0,H9-J9-K9)) -> 0 | AN9: =AN8+AM9 -> 0 | AO9: =MAX(0,Inputs!$B$23*MAX(0,AN9-P9)-AP8) -> 0 | AP9: =AP8+AO9 -> 0 | AQ9: =AM9-AO9 -> 0 | AR9: =MAX(0,Inputs!$B$23*MAX(0,AN9+I9-P9)-AP9) -> 0 | AS9: =I9-AR9 -> 13.29623 | AT9: =AT8+AQ9 -> 0 | AU9: =-L9+AQ9 -> -4.7875 | AV9: =IF(B9<Inputs!$B$31,AU9,IF(B9=Inputs!$B$31,AU9+AS9,0)) -> -4.7875 | AW9: =IF(P9>0,(AT9+AS9)/P9,0) -> 0.92576013
A10: =A9+1 -> 4 | B10: =EOMONTH(Inputs!$B$17,3*(A10-1)) -> 45291 | C10: =IF(A10<=Inputs!$B$18,1,0) -> 1 | D10: =I9 -> 13.29623 | E10: =IF(C10=1,Inputs!$B$19*Inputs!$B$13/Inputs!$B$18,0) -> 4.25 | F10: =D10*((1+Inputs!$B$24)^(1/4)-1) -> 0.56172098 | G10: =IF(A10=MAX($A$7:$A$46),1,IF(A10<Inputs!$B$25,0,MIN(1,Inputs!$B$26+Inputs!$B$27*(A10-Inputs!$B$25)))) -> 0 | H10: =G10*(D10+E10+F10) -> 0 | I10: =D10+E10+F10-H10 -> 18.107951 | J10: =IF(C10=1,Inputs!$B$20*Inputs!$B$13/4,Inputs!$B$21*D10/4) -> 0.5 | K10: =Inputs!$B$22*Inputs!$B$13/4 -> 0.0375 | L10: =IF(C10=1,MIN(E10+J10+K10,Inputs!$B$13-P9),0) -> 4.7875 | M10: =MAX(0,IF(C10=1,H10,H10-J10-K10)-AH10-AI10+AK10) -> 0 | N10: =MAX(0,Inputs!$B$23*MAX(0,Q10-P10)-R9) -> 0 | O10: =M10-N10 -> 0 | P10: =P9+L10 -> 19.15 | Q10: =Q9+M10 -> 0 | R10: =R9+N10 -> 0 | S10: =MAX(0,Inputs!$B$23*MAX(0,Q10+I10-AJ10-P10)-R10) -> 0 | T10: =I10-AJ10-S10 -> 18.107951 | U10: =U9+O10 -> 0 | V10: =IF(P10>0,U10/P10,0) -> 0 | W10: =IF(P10>0,T10/P10,0) -> 0.9455849 | X10: =V10+W10 -> 0.9455849 | Y10: =-L10+O10 -> -4.7875 | Z10: =IF(B10<Inputs!$B$31,Y10,IF(B10=Inputs!$B$31,Y10+T10,0)) -> -4.7875 | AA10: =-E10+H10 -> -4.25 | AB10: =IF(B10<Inputs!$B$31,AA10,IF(B10=Inputs!$B$31,AA10+I10,0)) -> -4.25 | AC10: =Inputs!$B$13-P10 -> 80.85 | AD10: =N10+S10-S9 -> 0 | AE10: =AJ9 -> 0 | AF10: =IF(AND(Inputs!$B$35=1,A10=Inputs!$B$36),MIN(Inputs!$B$37*I10,Inputs!$B$38),0) -> 0 | AG10: =Inputs!$B$40*AF10 -> 0 | AH10: =Inputs!$B$39/4*AE10 -> 0 | AI10: =IF(A10=MAX($A$7:$A$46),AE10,MIN(AE10,Inputs!$B$41*MAX(0,IF(C10=1,H10,H10-J10-K10)-AH10))) -> 0 | AJ10: =AE10+AF10-AI10 -> 0 | AK10: =AF10-AG10 -> 0 | AL10: =IF(I10>0,AJ10/I10,0) -> 0 | AM10: =IF(C10=1,H10,MAX(0,H10-J10-K10)) -> 0 | AN10: =AN9+AM10 -> 0 | AO10: =MAX(0,Inputs!$B$23*MAX(0,AN10-P10)-AP9) -> 0 | AP10: =AP9+AO10 -> 0 | AQ10: =AM10-AO10 -> 0 | AR10: =MAX(0,Inputs!$B$23*MAX(0,AN10+I10-P10)-AP10) -> 0 | AS10: =I10-AR10 -> 18.107951 | AT10: =AT9+AQ10 -> 0 | AU10: =-L10+AQ10 -> -4.7875 | AV10: =IF(B10<Inputs!$B$31,AU10,IF(B10=Inputs!$B$31,AU10+AS10,0)) -> -4.7875 | AW10: =IF(P10>0,(AT10+AS10)/P10,0) -> 0.9455849
A11: =A10+1 -> 5 | B11: =EOMONTH(Inputs!$B$17,3*(A11-1)) -> 45382 | C11: =IF(A11<=Inputs!$B$18,1,0) -> 1 | D11: =I10 -> 18.107951 | E11: =IF(C11=1,Inputs!$B$19*Inputs!$B$13/Inputs!$B$18,0) -> 4.25 | F11: =D11*((1+Inputs!$B$24)^(1/4)-1) -> 0.765 | G11: =IF(A11=MAX($A$7:$A$46),1,IF(A11<Inputs!$B$25,0,MIN(1,Inputs!$B$26+Inputs!$B$27*(A11-Inputs!$B$25)))) -> 0 | H11: =G11*(D11+E11+F11) -> 0 | I11: =D11+E11+F11-H11 -> 23.122951 | J11: =IF(C11=1,Inputs!$B$20*Inputs!$B$13/4,Inputs!$B$21*D11/4) -> 0.5 | K11: =Inputs!$B$22*Inputs!$B$13/4 -> 0.0375 | L11: =IF(C11=1,MIN(E11+J11+K11,Inputs!$B$13-P10),0) -> 4.7875 | M11: =MAX(0,IF(C11=1,H11,H11-J11-K11)-AH11-AI11+AK11) -> 0 | N11: =MAX(0,Inputs!$B$23*MAX(0,Q11-P11)-R10) -> 0 | O11: =M11-N11 -> 0 | P11: =P10+L11 -> 23.9375 | Q11: =Q10+M11 -> 0 | R11: =R10+N11 -> 0 | S11: =MAX(0,Inputs!$B$23*MAX(0,Q11+I11-AJ11-P11)-R11) -> 0 | T11: =I11-AJ11-S11 -> 23.122951 | U11: =U10+O11 -> 0 | V11: =IF(P11>0,U11/P11,0) -> 0 | W11: =IF(P11>0,T11/P11,0) -> 0.96597184 | X11: =V11+W11 -> 0.96597184 | Y11: =-L11+O11 -> -4.7875 | Z11: =IF(B11<Inputs!$B$31,Y11,IF(B11=Inputs!$B$31,Y11+T11,0)) -> -4.7875 | AA11: =-E11+H11 -> -4.25 | AB11: =IF(B11<Inputs!$B$31,AA11,IF(B11=Inputs!$B$31,AA11+I11,0)) -> -4.25 | AC11: =Inputs!$B$13-P11 -> 76.0625 | AD11: =N11+S11-S10 -> 0 | AE11: =AJ10 -> 0 | AF11: =IF(AND(Inputs!$B$35=1,A11=Inputs!$B$36),MIN(Inputs!$B$37*I11,Inputs!$B$38),0) -> 0 | AG11: =Inputs!$B$40*AF11 -> 0 | AH11: =Inputs!$B$39/4*AE11 -> 0 | AI11: =IF(A11=MAX($A$7:$A$46),AE11,MIN(AE11,Inputs!$B$41*MAX(0,IF(C11=1,H11,H11-J11-K11)-AH11))) -> 0 | AJ11: =AE11+AF11-AI11 -> 0 | AK11: =AF11-AG11 -> 0 | AL11: =IF(I11>0,AJ11/I11,0) -> 0 | AM11: =IF(C11=1,H11,MAX(0,H11-J11-K11)) -> 0 | AN11: =AN10+AM11 -> 0 | AO11: =MAX(0,Inputs!$B$23*MAX(0,AN11-P11)-AP10) -> 0 | AP11: =AP10+AO11 -> 0 | AQ11: =AM11-AO11 -> 0 | AR11: =MAX(0,Inputs!$B$23*MAX(0,AN11+I11-P11)-AP11) -> 0 | AS11: =I11-AR11 -> 23.122951 | AT11: =AT10+AQ11 -> 0 | AU11: =-L11+AQ11 -> -4.7875 | AV11: =IF(B11<Inputs!$B$31,AU11,IF(B11=Inputs!$B$31,AU11+AS11,0)) -> -4.7875 | AW11: =IF(P11>0,(AT11+AS11)/P11,0) -> 0.96597184
A12: =A11+1 -> 6 | B12: =EOMONTH(Inputs!$B$17,3*(A12-1)) -> 45473 | C12: =IF(A12<=Inputs!$B$18,1,0) -> 1 | D12: =I11 -> 23.122951 | E12: =IF(C12=1,Inputs!$B$19*Inputs!$B$13/Inputs!$B$18,0) -> 4.25 | F12: =D12*((1+Inputs!$B$24)^(1/4)-1) -> 0.97686688 | G12: =IF(A12=MAX($A$7:$A$46),1,IF(A12<Inputs!$B$25,0,MIN(1,Inputs!$B$26+Inputs!$B$27*(A12-Inputs!$B$25)))) -> 0 | H12: =G12*(D12+E12+F12) -> 0 | I12: =D12+E12+F12-H12 -> 28.349818 | J12: =IF(C12=1,Inputs!$B$20*Inputs!$B$13/4,Inputs!$B$21*D12/4) -> 0.5 | K12: =Inputs!$B$22*Inputs!$B$13/4 -> 0.0375 | L12: =IF(C12=1,MIN(E12+J12+K12,Inputs!$B$13-P11),0) -> 4.7875 | M12: =MAX(0,IF(C12=1,H12,H12-J12-K12)-AH12-AI12+AK12) -> 0 | N12: =MAX(0,Inputs!$B$23*MAX(0,Q12-P12)-R11) -> 0 | O12: =M12-N12 -> 0 | P12: =P11+L12 -> 28.725 | Q12: =Q11+M12 -> 0 | R12: =R11+N12 -> 0 | S12: =MAX(0,Inputs!$B$23*MAX(0,Q12+I12-AJ12-P12)-R12) -> 0 | T12: =I12-AJ12-S12 -> 28.349818 | U12: =U11+O12 -> 0 | V12: =IF(P12>0,U12/P12,0) -> 0 | W12: =IF(P12>0,T12/P12,0) -> 0.98693883 | X12: =V12+W12 -> 0.98693883 | Y12: =-L12+O12 -> -4.7875 | Z12: =IF(B12<Inputs!$B$31,Y12,IF(B12=Inputs!$B$31,Y12+T12,0)) -> -4.7875 | AA12: =-E12+H12 -> -4.25 | AB12: =IF(B12<Inputs!$B$31,AA12,IF(B12=Inputs!$B$31,AA12+I12,0)) -> -4.25 | AC12: =Inputs!$B$13-P12 -> 71.275 | AD12: =N12+S12-S11 -> 0 | AE12: =AJ11 -> 0 | AF12: =IF(AND(Inputs!$B$35=1,A12=Inputs!$B$36),MIN(Inputs!$B$37*I12,Inputs!$B$38),0) -> 0 | AG12: =Inputs!$B$40*AF12 -> 0 | AH12: =Inputs!$B$39/4*AE12 -> 0 | AI12: =IF(A12=MAX($A$7:$A$46),AE12,MIN(AE12,Inputs!$B$41*MAX(0,IF(C12=1,H12,H12-J12-K12)-AH12))) -> 0 | AJ12: =AE12+AF12-AI12 -> 0 | AK12: =AF12-AG12 -> 0 | AL12: =IF(I12>0,AJ12/I12,0) -> 0 | AM12: =IF(C12=1,H12,MAX(0,H12-J12-K12)) -> 0 | AN12: =AN11+AM12 -> 0 | AO12: =MAX(0,Inputs!$B$23*MAX(0,AN12-P12)-AP11) -> 0 | AP12: =AP11+AO12 -> 0 | AQ12: =AM12-AO12 -> 0 | AR12: =MAX(0,Inputs!$B$23*MAX(0,AN12+I12-P12)-AP12) -> 0 | AS12: =I12-AR12 -> 28.349818 | AT12: =AT11+AQ12 -> 0 | AU12: =-L12+AQ12 -> -4.7875 | AV12: =IF(B12<Inputs!$B$31,AU12,IF(B12=Inputs!$B$31,AU12+AS12,0)) -> -4.7875 | AW12: =IF(P12>0,(AT12+AS12)/P12,0) -> 0.98693883
A13: =A12+1 -> 7 | B13: =EOMONTH(Inputs!$B$17,3*(A13-1)) -> 45565 | C13: =IF(A13<=Inputs!$B$18,1,0) -> 1 | D13: =I12 -> 28.349818 | E13: =IF(C13=1,Inputs!$B$19*Inputs!$B$13/Inputs!$B$18,0) -> 4.25 | F13: =D13*((1+Inputs!$B$24)^(1/4)-1) -> 1.1976844 | G13: =IF(A13=MAX($A$7:$A$46),1,IF(A13<Inputs!$B$25,0,MIN(1,Inputs!$B$26+Inputs!$B$27*(A13-Inputs!$B$25)))) -> 0 | H13: =G13*(D13+E13+F13) -> 0 | I13: =D13+E13+F13-H13 -> 33.797502 | J13: =IF(C13=1,Inputs!$B$20*Inputs!$B$13/4,Inputs!$B$21*D13/4) -> 0.5 | K13: =Inputs!$B$22*Inputs!$B$13/4 -> 0.0375 | L13: =IF(C13=1,MIN(E13+J13+K13,Inputs!$B$13-P12),0) -> 4.7875 | M13: =MAX(0,IF(C13=1,H13,H13-J13-K13)-AH13-AI13+AK13) -> 0 | N13: =MAX(0,Inputs!$B$23*MAX(0,Q13-P13)-R12) -> 0 | O13: =M13-N13 -> 0 | P13: =P12+L13 -> 33.5125 | Q13: =Q12+M13 -> 0 | R13: =R12+N13 -> 0 | S13: =MAX(0,Inputs!$B$23*MAX(0,Q13+I13-AJ13-P13)-R13) -> 0.057000436 | T13: =I13-AJ13-S13 -> 33.740502 | U13: =U12+O13 -> 0 | V13: =IF(P13>0,U13/P13,0) -> 0 | W13: =IF(P13>0,T13/P13,0) -> 1.0068035 | X13: =V13+W13 -> 1.0068035 | Y13: =-L13+O13 -> -4.7875 | Z13: =IF(B13<Inputs!$B$31,Y13,IF(B13=Inputs!$B$31,Y13+T13,0)) -> -4.7875 | AA13: =-E13+H13 -> -4.25 | AB13: =IF(B13<Inputs!$B$31,AA13,IF(B13=Inputs!$B$31,AA13+I13,0)) -> -4.25 | AC13: =Inputs!$B$13-P13 -> 66.4875 | AD13: =N13+S13-S12 -> 0.057000436 | AE13: =AJ12 -> 0 | AF13: =IF(AND(Inputs!$B$35=1,A13=Inputs!$B$36),MIN(Inputs!$B$37*I13,Inputs!$B$38),0) -> 0 | AG13: =Inputs!$B$40*AF13 -> 0 | AH13: =Inputs!$B$39/4*AE13 -> 0 | AI13: =IF(A13=MAX($A$7:$A$46),AE13,MIN(AE13,Inputs!$B$41*MAX(0,IF(C13=1,H13,H13-J13-K13)-AH13))) -> 0 | AJ13: =AE13+AF13-AI13 -> 0 | AK13: =AF13-AG13 -> 0 | AL13: =IF(I13>0,AJ13/I13,0) -> 0 | AM13: =IF(C13=1,H13,MAX(0,H13-J13-K13)) -> 0 | AN13: =AN12+AM13 -> 0 | AO13: =MAX(0,Inputs!$B$23*MAX(0,AN13-P13)-AP12) -> 0 | AP13: =AP12+AO13 -> 0 | AQ13: =AM13-AO13 -> 0 | AR13: =MAX(0,Inputs!$B$23*MAX(0,AN13+I13-P13)-AP13) -> 0.057000436 | AS13: =I13-AR13 -> 33.740502 | AT13: =AT12+AQ13 -> 0 | AU13: =-L13+AQ13 -> -4.7875 | AV13: =IF(B13<Inputs!$B$31,AU13,IF(B13=Inputs!$B$31,AU13+AS13,0)) -> -4.7875 | AW13: =IF(P13>0,(AT13+AS13)/P13,0) -> 1.0068035
A14: =A13+1 -> 8 | B14: =EOMONTH(Inputs!$B$17,3*(A14-1)) -> 45657 | C14: =IF(A14<=Inputs!$B$18,1,0) -> 1 | D14: =I13 -> 33.797502 | E14: =IF(C14=1,Inputs!$B$19*Inputs!$B$13/Inputs!$B$18,0) -> 4.25 | F14: =D14*((1+Inputs!$B$24)^(1/4)-1) -> 1.4278308 | G14: =IF(A14=MAX($A$7:$A$46),1,IF(A14<Inputs!$B$25,0,MIN(1,Inputs!$B$26+Inputs!$B$27*(A14-Inputs!$B$25)))) -> 0 | H14: =G14*(D14+E14+F14) -> 0 | I14: =D14+E14+F14-H14 -> 39.475333 | J14: =IF(C14=1,Inputs!$B$20*Inputs!$B$13/4,Inputs!$B$21*D14/4) -> 0.5 | K14: =Inputs!$B$22*Inputs!$B$13/4 -> 0.0375 | L14: =IF(C14=1,MIN(E14+J14+K14,Inputs!$B$13-P13),0) -> 4.7875 | M14: =MAX(0,IF(C14=1,H14,H14-J14-K14)-AH14-AI14+AK14) -> 0 | N14: =MAX(0,Inputs!$B$23*MAX(0,Q14-P14)-R13) -> 0 | O14: =M14-N14 -> 0 | P14: =P13+L14 -> 38.3 | Q14: =Q13+M14 -> 0 | R14: =R13+N14 -> 0 | S14: =MAX(0,Inputs!$B$23*MAX(0,Q14+I14-AJ14-P14)-R14) -> 0.23506659 | T14: =I14-AJ14-S14 -> 39.240266 | U14: =U13+O14 -> 0 | V14: =IF(P14>0,U14/P14,0) -> 0 | W14: =IF(P14>0,T14/P14,0) -> 1.02455 | X14: =V14+W14 -> 1.02455 | Y14: =-L14+O14 -> -4.7875 | Z14: =IF(B14<Inputs!$B$31,Y14,IF(B14=Inputs!$B$31,Y14+T14,0)) -> -4.7875 | AA14: =-E14+H14 -> -4.25 | AB14: =IF(B14<Inputs!$B$31,AA14,IF(B14=Inputs!$B$31,AA14+I14,0)) -> -4.25 | AC14: =Inputs!$B$13-P14 -> 61.7 | AD14: =N14+S14-S13 -> 0.17806615 | AE14: =AJ13 -> 0 | AF14: =IF(AND(Inputs!$B$35=1,A14=Inputs!$B$36),MIN(Inputs!$B$37*I14,Inputs!$B$38),0) -> 0 | AG14: =Inputs!$B$40*AF14 -> 0 | AH14: =Inputs!$B$39/4*AE14 -> 0 | AI14: =IF(A14=MAX($A$7:$A$46),AE14,MIN(AE14,Inputs!$B$41*MAX(0,IF(C14=1,H14,H14-J14-K14)-AH14))) -> 0 | AJ14: =AE14+AF14-AI14 -> 0 | AK14: =AF14-AG14 -> 0 | AL14: =IF(I14>0,AJ14/I14,0) -> 0 | AM14: =IF(C14=1,H14,MAX(0,H14-J14-K14)) -> 0 | AN14: =AN13+AM14 -> 0 | AO14: =MAX(0,Inputs!$B$23*MAX(0,AN14-P14)-AP13) -> 0 | AP14: =AP13+AO14 -> 0 | AQ14: =AM14-AO14 -> 0 | AR14: =MAX(0,Inputs!$B$23*MAX(0,AN14+I14-P14)-AP14) -> 0.23506659 | AS14: =I14-AR14 -> 39.240266 | AT14: =AT13+AQ14 -> 0 | AU14: =-L14+AQ14 -> -4.7875 | AV14: =IF(B14<Inputs!$B$31,AU14,IF(B14=Inputs!$B$31,AU14+AS14,0)) -> -4.7875 | AW14: =IF(P14>0,(AT14+AS14)/P14,0) -> 1.02455
A15: =A14+1 -> 9 | B15: =EOMONTH(Inputs!$B$17,3*(A15-1)) -> 45747 | C15: =IF(A15<=Inputs!$B$18,1,0) -> 1 | D15: =I14 -> 39.475333 | E15: =IF(C15=1,Inputs!$B$19*Inputs!$B$13/Inputs!$B$18,0) -> 4.25 | F15: =D15*((1+Inputs!$B$24)^(1/4)-1) -> 1.6677 | G15: =IF(A15=MAX($A$7:$A$46),1,IF(A15<Inputs!$B$25,0,MIN(1,Inputs!$B$26+Inputs!$B$27*(A15-Inputs!$B$25)))) -> 0 | H15: =G15*(D15+E15+F15) -> 0 | I15: =D15+E15+F15-H15 -> 45.393033 | J15: =IF(C15=1,Inputs!$B$20*Inputs!$B$13/4,Inputs!$B$21*D15/4) -> 0.5 | K15: =Inputs!$B$22*Inputs!$B$13/4 -> 0.0375 | L15: =IF(C15=1,MIN(E15+J15+K15,Inputs!$B$13-P14),0) -> 4.7875 | M15: =MAX(0,IF(C15=1,H15,H15-J15-K15)-AH15-AI15+AK15) -> 0 | N15: =MAX(0,Inputs!$B$23*MAX(0,Q15-P15)-R14) -> 0 | O15: =M15-N15 -> 0 | P15: =P14+L15 -> 43.0875 | Q15: =Q14+M15 -> 0 | R15: =R14+N15 -> 0 | S15: =MAX(0,Inputs!$B$23*MAX(0,Q15+I15-AJ15-P15)-R15) -> 0.46110659 | T15: =I15-AJ15-S15 -> 44.931926 | U15: =U14+O15 -> 0 | V15: =IF(P15>0,U15/P15,0) -> 0 | W15: =IF(P15>0,T15/P15,0) -> 1.0428065 | X15: =V15+W15 -> 1.0428065 | Y15: =-L15+O15 -> -4.7875 | Z15: =IF(B15<Inputs!$B$31,Y15,IF(B15=Inputs!$B$31,Y15+T15,0)) -> -4.7875 | AA15: =-E15+H15 -> -4.25 | AB15: =IF(B15<Inputs!$B$31,AA15,IF(B15=Inputs!$B$31,AA15+I15,0)) -> -4.25 | AC15: =Inputs!$B$13-P15 -> 56.9125 | AD15: =N15+S15-S14 -> 0.22604 | AE15: =AJ14 -> 0 | AF15: =IF(AND(Inputs!$B$35=1,A15=Inputs!$B$36),MIN(Inputs!$B$37*I15,Inputs!$B$38),0) -> 0 | AG15: =Inputs!$B$40*AF15 -> 0 | AH15: =Inputs!$B$39/4*AE15 -> 0 | AI15: =IF(A15=MAX($A$7:$A$46),AE15,MIN(AE15,Inputs!$B$41*MAX(0,IF(C15=1,H15,H15-J15-K15)-AH15))) -> 0 | AJ15: =AE15+AF15-AI15 -> 0 | AK15: =AF15-AG15 -> 0 | AL15: =IF(I15>0,AJ15/I15,0) -> 0 | AM15: =IF(C15=1,H15,MAX(0,H15-J15-K15)) -> 0 | AN15: =AN14+AM15 -> 0 | AO15: =MAX(0,Inputs!$B$23*MAX(0,AN15-P15)-AP14) -> 0 | AP15: =AP14+AO15 -> 0 | AQ15: =AM15-AO15 -> 0 | AR15: =MAX(0,Inputs!$B$23*MAX(0,AN15+I15-P15)-AP15) -> 0.46110659 | AS15: =I15-AR15 -> 44.931926 | AT15: =AT14+AQ15 -> 0 | AU15: =-L15+AQ15 -> -4.7875 | AV15: =IF(B15<Inputs!$B$31,AU15,IF(B15=Inputs!$B$31,AU15+AS15,0)) -> -4.7875 | AW15: =IF(P15>0,(AT15+AS15)/P15,0) -> 1.0428065
A16: =A15+1 -> 10 | B16: =EOMONTH(Inputs!$B$17,3*(A16-1)) -> 45838 | C16: =IF(A16<=Inputs!$B$18,1,0) -> 1 | D16: =I15 -> 45.393033 | E16: =IF(C16=1,Inputs!$B$19*Inputs!$B$13/Inputs!$B$18,0) -> 4.25 | F16: =D16*((1+Inputs!$B$24)^(1/4)-1) -> 1.9177029 | G16: =IF(A16=MAX($A$7:$A$46),1,IF(A16<Inputs!$B$25,0,MIN(1,Inputs!$B$26+Inputs!$B$27*(A16-Inputs!$B$25)))) -> 0 | H16: =G16*(D16+E16+F16) -> 0 | I16: =D16+E16+F16-H16 -> 51.560736 | J16: =IF(C16=1,Inputs!$B$20*Inputs!$B$13/4,Inputs!$B$21*D16/4) -> 0.5 | K16: =Inputs!$B$22*Inputs!$B$13/4 -> 0.0375 | L16: =IF(C16=1,MIN(E16+J16+K16,Inputs!$B$13-P15),0) -> 4.7875 | M16: =MAX(0,IF(C16=1,H16,H16-J16-K16)-AH16-AI16+AK16) -> 0 | N16: =MAX(0,Inputs!$B$23*MAX(0,Q16-P16)-R15) -> 0 | O16: =M16-N16 -> 0 | P16: =P15+L16 -> 47.875 | Q16: =Q15+M16 -> 0 | R16: =R15+N16 -> 0 | S16: =MAX(0,Inputs!$B$23*MAX(0,Q16+I16-AJ16-P16)-R16) -> 0.73714717 | T16: =I16-AJ16-S16 -> 50.823589 | U16: =U15+O16 -> 0 | V16: =IF(P16>0,U16/P16,0) -> 0 | W16: =IF(P16>0,T16/P16,0) -> 1.0615893 | X16: =V16+W16 -> 1.0615893 | Y16: =-L16+O16 -> -4.7875 | Z16: =IF(B16<Inputs!$B$31,Y16,IF(B16=Inputs!$B$31,Y16+T16,0)) -> -4.7875 | AA16: =-E16+H16 -> -4.25 | AB16: =IF(B16<Inputs!$B$31,AA16,IF(B16=Inputs!$B$31,AA16+I16,0)) -> -4.25 | AC16: =Inputs!$B$13-P16 -> 52.125 | AD16: =N16+S16-S15 -> 0.27604058 | AE16: =AJ15 -> 0 | AF16: =IF(AND(Inputs!$B$35=1,A16=Inputs!$B$36),MIN(Inputs!$B$37*I16,Inputs!$B$38),0) -> 0 | AG16: =Inputs!$B$40*AF16 -> 0 | AH16: =Inputs!$B$39/4*AE16 -> 0 | AI16: =IF(A16=MAX($A$7:$A$46),AE16,MIN(AE16,Inputs!$B$41*MAX(0,IF(C16=1,H16,H16-J16-K16)-AH16))) -> 0 | AJ16: =AE16+AF16-AI16 -> 0 | AK16: =AF16-AG16 -> 0 | AL16: =IF(I16>0,AJ16/I16,0) -> 0 | AM16: =IF(C16=1,H16,MAX(0,H16-J16-K16)) -> 0 | AN16: =AN15+AM16 -> 0 | AO16: =MAX(0,Inputs!$B$23*MAX(0,AN16-P16)-AP15) -> 0 | AP16: =AP15+AO16 -> 0 | AQ16: =AM16-AO16 -> 0 | AR16: =MAX(0,Inputs!$B$23*MAX(0,AN16+I16-P16)-AP16) -> 0.73714717 | AS16: =I16-AR16 -> 50.823589 | AT16: =AT15+AQ16 -> 0 | AU16: =-L16+AQ16 -> -4.7875 | AV16: =IF(B16<Inputs!$B$31,AU16,IF(B16=Inputs!$B$31,AU16+AS16,0)) -> -4.7875 | AW16: =IF(P16>0,(AT16+AS16)/P16,0) -> 1.0615893
A17: =A16+1 -> 11 | B17: =EOMONTH(Inputs!$B$17,3*(A17-1)) -> 45930 | C17: =IF(A17<=Inputs!$B$18,1,0) -> 1 | D17: =I16 -> 51.560736 | E17: =IF(C17=1,Inputs!$B$19*Inputs!$B$13/Inputs!$B$18,0) -> 4.25 | F17: =D17*((1+Inputs!$B$24)^(1/4)-1) -> 2.1782676 | G17: =IF(A17=MAX($A$7:$A$46),1,IF(A17<Inputs!$B$25,0,MIN(1,Inputs!$B$26+Inputs!$B$27*(A17-Inputs!$B$25)))) -> 0 | H17: =G17*(D17+E17+F17) -> 0 | I17: =D17+E17+F17-H17 -> 57.989003 | J17: =IF(C17=1,Inputs!$B$20*Inputs!$B$13/4,Inputs!$B$21*D17/4) -> 0.5 | K17: =Inputs!$B$22*Inputs!$B$13/4 -> 0.0375 | L17: =IF(C17=1,MIN(E17+J17+K17,Inputs!$B$13-P16),0) -> 4.7875 | M17: =MAX(0,IF(C17=1,H17,H17-J17-K17)-AH17-AI17+AK17) -> 0 | N17: =MAX(0,Inputs!$B$23*MAX(0,Q17-P17)-R16) -> 0 | O17: =M17-N17 -> 0 | P17: =P16+L17 -> 52.6625 | Q17: =Q16+M17 -> 0 | R17: =R16+N17 -> 0 | S17: =MAX(0,Inputs!$B$23*MAX(0,Q17+I17-AJ17-P17)-R17) -> 1.0653007 | T17: =I17-AJ17-S17 -> 56.923703 | U17: =U16+O17 -> 0 | V17: =IF(P17>0,U17/P17,0) -> 0 | W17: =IF(P17>0,T17/P17,0) -> 1.0809153 | X17: =V17+W17 -> 1.0809153 | Y17: =-L17+O17 -> -4.7875 | Z17: =IF(B17<Inputs!$B$31,Y17,IF(B17=Inputs!$B$31,Y17+T17,0)) -> -4.7875 | AA17: =-E17+H17 -> -4.25 | AB17: =IF(B17<Inputs!$B$31,AA17,IF(B17=Inputs!$B$31,AA17+I17,0)) -> -4.25 | AC17: =Inputs!$B$13-P17 -> 47.3375 | AD17: =N17+S17-S16 -> 0.32815352 | AE17: =AJ16 -> 0 | AF17: =IF(AND(Inputs!$B$35=1,A17=Inputs!$B$36),MIN(Inputs!$B$37*I17,Inputs!$B$38),0) -> 0 | AG17: =Inputs!$B$40*AF17 -> 0 | AH17: =Inputs!$B$39/4*AE17 -> 0 | AI17: =IF(A17=MAX($A$7:$A$46),AE17,MIN(AE17,Inputs!$B$41*MAX(0,IF(C17=1,H17,H17-J17-K17)-AH17))) -> 0 | AJ17: =AE17+AF17-AI17 -> 0 | AK17: =AF17-AG17 -> 0 | AL17: =IF(I17>0,AJ17/I17,0) -> 0 | AM17: =IF(C17=1,H17,MAX(0,H17-J17-K17)) -> 0 | AN17: =AN16+AM17 -> 0 | AO17: =MAX(0,Inputs!$B$23*MAX(0,AN17-P17)-AP16) -> 0 | AP17: =AP16+AO17 -> 0 | AQ17: =AM17-AO17 -> 0 | AR17: =MAX(0,Inputs!$B$23*MAX(0,AN17+I17-P17)-AP17) -> 1.0653007 | AS17: =I17-AR17 -> 56.923703 | AT17: =AT16+AQ17 -> 0 | AU17: =-L17+AQ17 -> -4.7875 | AV17: =IF(B17<Inputs!$B$31,AU17,IF(B17=Inputs!$B$31,AU17+AS17,0)) -> -4.7875 | AW17: =IF(P17>0,(AT17+AS17)/P17,0) -> 1.0809153
A18: =A17+1 -> 12 | B18: =EOMONTH(Inputs!$B$17,3*(A18-1)) -> 46022 | C18: =IF(A18<=Inputs!$B$18,1,0) -> 1 | D18: =I17 -> 57.989003 | E18: =IF(C18=1,Inputs!$B$19*Inputs!$B$13/Inputs!$B$18,0) -> 4.25 | F18: =D18*((1+Inputs!$B$24)^(1/4)-1) -> 2.4498403 | G18: =IF(A18=MAX($A$7:$A$46),1,IF(A18<Inputs!$B$25,0,MIN(1,Inputs!$B$26+Inputs!$B$27*(A18-Inputs!$B$25)))) -> 0 | H18: =G18*(D18+E18+F18) -> 0 | I18: =D18+E18+F18-H18 -> 64.688844 | J18: =IF(C18=1,Inputs!$B$20*Inputs!$B$13/4,Inputs!$B$21*D18/4) -> 0.5 | K18: =Inputs!$B$22*Inputs!$B$13/4 -> 0.0375 | L18: =IF(C18=1,MIN(E18+J18+K18,Inputs!$B$13-P17),0) -> 4.7875 | M18: =MAX(0,IF(C18=1,H18,H18-J18-K18)-AH18-AI18+AK18) -> 0 | N18: =MAX(0,Inputs!$B$23*MAX(0,Q18-P18)-R17) -> 0 | O18: =M18-N18 -> 0 | P18: =P17+L18 -> 57.45 | Q18: =Q17+M18 -> 0 | R18: =R17+N18 -> 0 | S18: =MAX(0,Inputs!$B$23*MAX(0,Q18+I18-AJ18-P18)-R18) -> 1.4477688 | T18: =I18-AJ18-S18 -> 63.241075 | U18: =U17+O18 -> 0 | V18: =IF(P18>0,U18/P18,0) -> 0 | W18: =IF(P18>0,T18/P18,0) -> 1.100802 | X18: =V18+W18 -> 1.100802 | Y18: =-L18+O18 -> -4.7875 | Z18: =IF(B18<Inputs!$B$31,Y18,IF(B18=Inputs!$B$31,Y18+T18,0)) -> -4.7875 | AA18: =-E18+H18 -> -4.25 | AB18: =IF(B18<Inputs!$B$31,AA18,IF(B18=Inputs!$B$31,AA18+I18,0)) -> -4.25 | AC18: =Inputs!$B$13-P18 -> 42.55 | AD18: =N18+S18-S17 -> 0.38246806 | AE18: =AJ17 -> 0 | AF18: =IF(AND(Inputs!$B$35=1,A18=Inputs!$B$36),MIN(Inputs!$B$37*I18,Inputs!$B$38),0) -> 0 | AG18: =Inputs!$B$40*AF18 -> 0 | AH18: =Inputs!$B$39/4*AE18 -> 0 | AI18: =IF(A18=MAX($A$7:$A$46),AE18,MIN(AE18,Inputs!$B$41*MAX(0,IF(C18=1,H18,H18-J18-K18)-AH18))) -> 0 | AJ18: =AE18+AF18-AI18 -> 0 | AK18: =AF18-AG18 -> 0 | AL18: =IF(I18>0,AJ18/I18,0) -> 0 | AM18: =IF(C18=1,H18,MAX(0,H18-J18-K18)) -> 0 | AN18: =AN17+AM18 -> 0 | AO18: =MAX(0,Inputs!$B$23*MAX(0,AN18-P18)-AP17) -> 0 | AP18: =AP17+AO18 -> 0 | AQ18: =AM18-AO18 -> 0 | AR18: =MAX(0,Inputs!$B$23*MAX(0,AN18+I18-P18)-AP18) -> 1.4477688 | AS18: =I18-AR18 -> 63.241075 | AT18: =AT17+AQ18 -> 0 | AU18: =-L18+AQ18 -> -4.7875 | AV18: =IF(B18<Inputs!$B$31,AU18,IF(B18=Inputs!$B$31,AU18+AS18,0)) -> -4.7875 | AW18: =IF(P18>0,(AT18+AS18)/P18,0) -> 1.100802
... A46: =A45+1 -> 40 | B46: =EOMONTH(Inputs!$B$17,3*(A46-1)) -> 48579 | C46: =IF(A46<=Inputs!$B$18,1,0) -> 0 | D46: =I45 -> 1.2238677 | E46: =IF(C46=1,Inputs!$B$19*Inputs!$B$13/Inputs!$B$18,0) -> 0 | F46: =D46*((1+Inputs!$B$24)^(1/4)-1) -> 0.051704292 | G46: =IF(A46=MAX($A$7:$A$46),1,IF(A46<Inputs!$B$25,0,MIN(1,Inputs!$B$26+Inputs!$B$27*(A46-Inputs!$B$25)))) -> 1 | H46: =G46*(D46+E46+F46) -> 1.275572 | I46: =D46+E46+F46-H46 -> 0 | J46: =IF(C46=1,Inputs!$B$20*Inputs!$B$13/4,Inputs!$B$21*D46/4) -> 0.0045895039 | K46: =Inputs!$B$22*Inputs!$B$13/4 -> 0.0375 | L46: =IF(C46=1,MIN(E46+J46+K46,Inputs!$B$13-P45),0) -> 0 | M46: =MAX(0,IF(C46=1,H46,H46-J46-K46)-AH46-AI46+AK46) -> 1.2334825 | N46: =MAX(0,Inputs!$B$23*MAX(0,Q46-P46)-R45) -> 0.2466965 | O46: =M46-N46 -> 0.98678599 | P46: =P45+L46 -> 95.75 | Q46: =Q45+M46 -> 155.27782 | R46: =R45+N46 -> 11.905563 | S46: =MAX(0,Inputs!$B$23*MAX(0,Q46+I46-AJ46-P46)-R46) -> 0 | T46: =I46-AJ46-S46 -> 0 | U46: =U45+O46 -> 143.37225 | V46: =IF(P46>0,U46/P46,0) -> 1.4973604 | W46: =IF(P46>0,T46/P46,0) -> 0 | X46: =V46+W46 -> 1.4973604 | Y46: =-L46+O46 -> 0.98678599 | Z46: =IF(B46<Inputs!$B$31,Y46,IF(B46=Inputs!$B$31,Y46+T46,0)) -> 0 | AA46: =-E46+H46 -> 1.275572 | AB46: =IF(B46<Inputs!$B$31,AA46,IF(B46=Inputs!$B$31,AA46+I46,0)) -> 0 | AC46: =Inputs!$B$13-P46 -> 4.25 | AD46: =N46+S46-S45 -> 0.0019229577 | AE46: =AJ45 -> 0 | AF46: =IF(AND(Inputs!$B$35=1,A46=Inputs!$B$36),MIN(Inputs!$B$37*I46,Inputs!$B$38),0) -> 0 | AG46: =Inputs!$B$40*AF46 -> 0 | AH46: =Inputs!$B$39/4*AE46 -> 0 | AI46: =IF(A46=MAX($A$7:$A$46),AE46,MIN(AE46,Inputs!$B$41*MAX(0,IF(C46=1,H46,H46-J46-K46)-AH46))) -> 0 | AJ46: =AE46+AF46-AI46 -> 0 | AK46: =AF46-AG46 -> 0 | AL46: =IF(I46>0,AJ46/I46,0) -> 0 | AM46: =IF(C46=1,H46,MAX(0,H46-J46-K46)) -> 1.2334825 | AN46: =AN45+AM46 -> 156.40581 | AO46: =MAX(0,Inputs!$B$23*MAX(0,AN46-P46)-AP45) -> 0.2466965 | AP46: =AP45+AO46 -> 12.131162 | AQ46: =AM46-AO46 -> 0.98678599 | AR46: =MAX(0,Inputs!$B$23*MAX(0,AN46+I46-P46)-AP46) -> 0 | AS46: =I46-AR46 -> 0 | AT46: =AT45+AQ46 -> 144.27465 | AU46: =-L46+AQ46 -> 0.98678599 | AV46: =IF(B46<Inputs!$B$31,AU46,IF(B46=Inputs!$B$31,AU46+AS46,0)) -> 0 | AW46: =IF(P46>0,(AT46+AS46)/P46,0) -> 1.5067848
A48: Total | E48: =SUM(E7:E46) -> 85 | F48: =SUM(F7:F46) -> 74.979022 | H48: =SUM(H7:H46) -> 159.97902 | J48: =SUM(J7:J46) -> 12.823213 | K48: =SUM(K7:K46) -> 1.5 | L48: =SUM(L7:L46) -> 95.75 | M48: =SUM(M7:M46) -> 155.27782 | N48: =SUM(N7:N46) -> 11.905563 | O48: =SUM(O7:O46) -> 143.37225 | AF48: =SUM(AF7:AF46) -> 14.227198 | AG48: =SUM(AG7:AG46) -> 0.14227198 | AH48: =SUM(AH7:AH46) -> 0.98571964 | AI48: =SUM(AI7:AI46) -> 14.227198

Sheet Returns
A1: Returns summary (investor level, net of fees, loan costs and carry)
A2: Measured at the as-of date on the Inputs sheet.
A4: As-of date | B4: =Inputs!B31 -> 47118
A5: Row index of as-of quarter (helper) | B5: =MATCH(B4,Fund!$B$7:$B$46,0) -> 24
A6: Quarter number | B6: =INDEX(Fund!$A$7:$A$46,$B$5) -> 24
A8: Net (investor) metrics | B8: Value | C8: Definition
A9: Total commitments ($mm) | B9: =Inputs!B13 -> 100 | C9: Sum of investor commitments.
A10: Paid-in capital ($mm) | B10: =INDEX(Fund!$P$7:$P$46,$B$5) -> 95.75 | C10: Cumulative capital calls to the as-of date.
A11: % of commitments called | B11: =B10/B9 -> 0.9575
A12: Unfunded commitment ($mm) | B12: =B9-B10 -> 4.25
A13: Cumulative distributions ($mm) | B13: =INDEX(Fund!$U$7:$U$46,$B$5) -> 76.27013 | C13: Received by investors, after carried interest.
A14: Residual NAV ($mm) | B14: =INDEX(Fund!$T$7:$T$46,$B$5) -> 55.735487 | C14: Portfolio value less NAV loan balance less accrued (unrealised) carry.
A15: DPI | B15: =B13/B10 -> 0.79655488 | C15: Distributions / paid-in capital. Realised return.
A16: RVPI | B16: =B14/B10 -> 0.58209386 | C16: Residual NAV / paid-in capital. Unrealised return.
A17: TVPI | B17: =B15+B16 -> 1.3786487 | C17: DPI + RVPI. Total value / paid-in capital.
A18: Net IRR (XIRR) | B18: =XIRR(Fund!$Z$7:$Z$46,Fund!$B$7:$B$46) -> 0.11199238 | C18: Annualised, dated flows: -calls + distributions, with NAV as a terminal value at the as-of date. Levered if the NAV loan is on.
A21: Gross (portfolio) metrics | B21: Value | C21: Definition
A22: Cumulative investments ($mm) | B22: =SUMIFS(Fund!$E$7:$E$46,Fund!$B$7:$B$46,"<="&$B$4) -> 85
A23: Cumulative gross exit proceeds ($mm) | B23: =SUMIFS(Fund!$H$7:$H$46,Fund!$B$7:$B$46,"<="&$B$4) -> 72.80785
A24: Portfolio value ($mm) | B24: =INDEX(Fund!$I$7:$I$46,$B$5) -> 70.691671 | C24: Before carry, fees and expenses.
A25: Gross MOIC | B25: =(B23+B24)/B22 -> 1.6882297 | C25: (Proceeds + portfolio value) / invested cost.
A26: Gross IRR (XIRR) | B26: =XIRR(Fund!$AB$7:$AB$46,Fund!$B$7:$B$46) -> 0.17975699 | C26: On investment and exit flows, before fees, expenses and carry.
A27: Gross-to-net IRR spread | B27: =B26-B18 -> 0.067764603 | C27: Cost of fees, expenses and carry.
A30: Fund life totals (to final quarter) | B30: Value
A31: Total capital called ($mm) | B31: =Fund!L48 -> 95.75
A32: Total net distributions ($mm) | B32: =Fund!O48 -> 143.37225
A33: Total management fees ($mm) | B33: =Fund!J48 -> 12.823213
A34: Total fund expenses ($mm) | B34: =Fund!K48 -> 1.5
A35: Total carried interest paid ($mm) | B35: =Fund!N48 -> 11.905563
A36: Final TVPI (all distributed) | B36: =B32/B31 -> 1.4973604

Sheet NAV Loan
A1: NAV loan extension: impact on investor returns
A2: Same fund run twice: with the NAV loan (as set on Inputs) and without it. US$ millions.
A4: NAV loan switch (1 = on) | B4: =Inputs!B35 -> 1
A5: Draw quarter end | B5: =IFERROR(INDEX(Fund!$B$7:$B$46,Inputs!B36),"n/a") -> 46843
A6: Advance rate (LTV) / interest rate p.a. | B6: =Inputs!B37 -> 0.15 | C6: =Inputs!B39 -> 0.09
A8: Investor returns at the as-of date | B8: With NAV loan | C8: Without loan | D8: Difference | E8: Reading it
A9: Paid-in capital ($mm) | B9: =Returns!B10 -> 95.75 | C9: =INDEX(Fund!$P$7:$P$46,Returns!$B$5) -> 95.75 | D9: =B9-C9 -> 0 | E9: Capital calls are identical: the loan does not change what investors fund.
A10: Cumulative distributions ($mm) | B10: =Returns!B13 -> 76.27013 | C10: =INDEX(Fund!$AT$7:$AT$46,Returns!$B$5) -> 71.297431 | D10: =B10-C10 -> 4.9726985 | E10: Higher with the loan once the special distribution is paid, until the loan is repaid from exits.
A11: Residual NAV ($mm) | B11: =Returns!B14 -> 55.735487 | C11: =INDEX(Fund!$AS$7:$AS$46,Returns!$B$5) -> 61.44385 | D11: =B11-C11 -> -5.7083635 | E11: Lower with the loan outstanding: NAV is net of the debt.
A12: DPI | B12: =Returns!B15 -> 0.79655488 | C12: =C10/C9 -> 0.74462069 | D12: =B12-C12 -> 0.051934188 | E12: Realised return: pulled forward by the recap.
A13: RVPI | B13: =Returns!B16 -> 0.58209386 | C13: =C11/C9 -> 0.64171123 | D13: =B13-C13 -> -0.059617373
A14: TVPI | B14: =Returns!B17 -> 1.3786487 | C14: =C12+C13 -> 1.3863319 | D14: =B14-C14 -> -0.0076831851 | E14: Total value: reduced by interest and the arrangement fee.
A15: Net IRR (XIRR) | B15: =Returns!B18 -> 0.11199238 | C15: =XIRR(Fund!$AV$7:$AV$46,Fund!$B$7:$B$46) -> 0.11151399 | D15: =B15-C15 -> 0.00047838783 | E15: IRR rewards getting cash back sooner, which is why sponsors use NAV loans.
A18: Fund life (to final quarter) | B18: With NAV loan | C18: Without loan | D18: Difference
A19: Total net distributions ($mm) | B19: =Fund!O48 -> 143.37225 | C19: =SUM(Fund!$AQ$7:$AQ$46) -> 144.27465 | D19: =B19-C19 -> -0.90239329
A20: Final TVPI (all distributed) | B20: =B19/Fund!L48 -> 1.4973604 | C20: =C19/Fund!L48 -> 1.5067848 | D20: =B20-C20 -> -0.009424473
A21: Net IRR since inception | B21: =XIRR(Fund!$Y$7:$Y$46,Fund!$B$7:$B$46) -> 0.11791064 | C21: =XIRR(Fund!$AU$7:$AU$46,Fund!$B$7:$B$46) -> 0.11725129 | D21: =B21-C21 -> 0.0006593506
A22: Total carried interest paid ($mm) | B22: =Fund!N48 -> 11.905563 | C22: =SUM(Fund!$AO$7:$AO$46) -> 12.131162 | D22: =B22-C22 -> -0.22559832
A25: NAV loan summary | B25: Value
A26: Amount drawn ($mm) | B26: =Fund!AF48 -> 14.227198
A27: Arrangement fee ($mm) | B27: =Fund!AG48 -> 0.14227198
A28: Net cash distributed to investors at draw ($mm) | B28: =B26-B27 -> 14.084926
A29: Total interest paid ($mm) | B29: =Fund!AH48 -> 0.98571964
A30: Total cost of loan: interest + fee ($mm) | B30: =B27+B29 -> 1.1279916
A31: Total repaid ($mm) | B31: =Fund!AI48 -> 14.227198
A32: Peak loan-to-value (loan / portfolio value) | B32: =MAX(Fund!$AL$7:$AL$46) -> 0.15
A33: Quarter loan is fully repaid | B33: =IF(B26=0,"n/a",IFERROR(INDEX(Fund!$B$7:$B$46,Inputs!B36+COUNTIF(Fund!$AJ$7:$AJ$46,">0")),"n/a")) -> 47391

Sheet LP Statement
A1: LP capital account statement
A2: Select an investor and a period. Period should start the day after a quarter-end and end on a quarter-end. US$ millions.
A3: Investor | B3: LP A (institutional)
A4: Commitment ($mm) | B4: =INDEX(Inputs!$B$9:$B$12,MATCH($B$3,Inputs!$A$9:$A$12,0)) -> 40
A5: Share of fund | B5: =INDEX(Inputs!$C$9:$C$12,MATCH($B$3,Inputs!$A$9:$A$12,0)) -> 0.4
A6: Period start | B6: 46753 | C6: Inputs (change freely). Beginning balance = closing balance at the last quarter-end before the start date.
A7: Period end | B7: 47118
A10: Statement of capital account | B10: Period ($mm)
A11: Beginning capital balance | B11: =IFERROR($B$5*INDEX(Fund!$T$7:$T$46,MATCH($B$6-1,Fund!$B$7:$B$46,1)),0) -> 37.852086
A12: Contributions (capital calls) | B12: =$B$5*SUMIFS(Fund!$L$7:$L$46,Fund!$B$7:$B$46,">="&$B$6,Fund!$B$7:$B$46,"<="&$B$7) -> 0
A13: Distributions | B13: =-$B$5*SUMIFS(Fund!$O$7:$O$46,Fund!$B$7:$B$46,">="&$B$6,Fund!$B$7:$B$46,"<="&$B$7) -> -19.684665
A14: Allocated income / (loss):
A15: Portfolio gains | B15: =$B$5*SUMIFS(Fund!$F$7:$F$46,Fund!$B$7:$B$46,">="&$B$6,Fund!$B$7:$B$46,"<="&$B$7) -> 6.1304679
A16: Management fees | B16: =-$B$5*SUMIFS(Fund!$J$7:$J$46,Fund!$B$7:$B$46,">="&$B$6,Fund!$B$7:$B$46,"<="&$B$7) -> -0.54416771
A17: Fund expenses | B17: =-$B$5*SUMIFS(Fund!$K$7:$K$46,Fund!$B$7:$B$46,">="&$B$6,Fund!$B$7:$B$46,"<="&$B$7) -> -0.06
A18: NAV loan interest | B18: =-$B$5*SUMIFS(Fund!$AH$7:$AH$46,Fund!$B$7:$B$46,">="&$B$6,Fund!$B$7:$B$46,"<="&$B$7) -> -0.3109237
A19: NAV loan arrangement fee | B19: =-$B$5*SUMIFS(Fund!$AG$7:$AG$46,Fund!$B$7:$B$46,">="&$B$6,Fund!$B$7:$B$46,"<="&$B$7) -> -0.05690879
A20: Carried interest (paid + change in accrual) | B20: =-$B$5*SUMIFS(Fund!$AD$7:$AD$46,Fund!$B$7:$B$46,">="&$B$6,Fund!$B$7:$B$46,"<="&$B$7) -> -1.0316935
A21: Net allocated income / (loss) | B21: =SUM(B15:B20) -> 4.1267742
A22: Ending capital balance | B22: =B11+B12+B13+B21 -> 22.294195
A23: Check: fund NAV x share at period end (should equal above) | B23: =$B$5*INDEX(Fund!$T$7:$T$46,MATCH($B$7,Fund!$B$7:$B$46,1)) -> 22.294195
A24: Difference | B24: =ROUND(B22-B23,6) -> 0
A26: Inception to period end (memo) | B26: Value
A27: Cumulative contributions ($mm) | B27: =$B$5*INDEX(Fund!$P$7:$P$46,MATCH($B$7,Fund!$B$7:$B$46,1)) -> 38.3
A28: Cumulative distributions ($mm) | B28: =$B$5*INDEX(Fund!$U$7:$U$46,MATCH($B$7,Fund!$B$7:$B$46,1)) -> 30.508052
A29: Unfunded commitment ($mm) | B29: =$B$4-B27 -> 1.7
A30: DPI | B30: =IF(B27>0,B28/B27,0) -> 0.79655488 | C30: All investors are pro rata, so ratios and IRR are identical across investors; dollar amounts scale with commitment.
A31: RVPI | B31: =IF(B27>0,B23/B27,0) -> 0.58209386
A32: TVPI | B32: =B30+B31 -> 1.3786487
A35: Quarterly capital account roll-forward | B35: Beginning capital | C35: Contributions | D35: Distributions | E35: Net allocated income | F35: Ending capital | G35: Unfunded commitment | H35: Check vs fund NAV
A36: =Fund!B7 -> 45016 | B36: =$B$5*Fund!T6 -> 0 | C36: =$B$5*Fund!L7 -> 1.915 | D36: =-$B$5*Fund!O7 -> 0 | E36: =$B$5*(Fund!F7-Fund!J7-Fund!K7-Fund!AH7-Fund!AG7-Fund!AD7) -> -0.215 | F36: =B36+C36+D36+E36 -> 1.7 | G36: =$B$4-$B$5*Fund!P7 -> 38.085 | H36: =ROUND(F36-$B$5*Fund!T7,6) -> 0
A37: =Fund!B8 -> 45107 | B37: =$B$5*Fund!T7 -> 1.7 | C37: =$B$5*Fund!L8 -> 1.915 | D37: =-$B$5*Fund!O8 -> 0 | E37: =$B$5*(Fund!F8-Fund!J8-Fund!K8-Fund!AH8-Fund!AG8-Fund!AD8) -> -0.14318072 | F37: =B37+C37+D37+E37 -> 3.4718193 | G37: =$B$4-$B$5*Fund!P8 -> 36.17 | H37: =ROUND(F37-$B$5*Fund!T8,6) -> 0
A38: =Fund!B9 -> 45199 | B38: =$B$5*Fund!T8 -> 3.4718193 | C38: =$B$5*Fund!L9 -> 1.915 | D38: =-$B$5*Fund!O9 -> 0 | E38: =$B$5*(Fund!F9-Fund!J9-Fund!K9-Fund!AH9-Fund!AG9-Fund!AD9) -> -0.068327316 | F38: =B38+C38+D38+E38 -> 5.318492 | G38: =$B$4-$B$5*Fund!P9 -> 34.255 | H38: =ROUND(F38-$B$5*Fund!T9,6) -> 0
A39: =Fund!B10 -> 45291 | B39: =$B$5*Fund!T9 -> 5.318492 | C39: =$B$5*Fund!L10 -> 1.915 | D39: =-$B$5*Fund!O10 -> 0 | E39: =$B$5*(Fund!F10-Fund!J10-Fund!K10-Fund!AH10-Fund!AG10-Fund!AD10) -> 0.0096883912 | F39: =B39+C39+D39+E39 -> 7.2431804 | G39: =$B$4-$B$5*Fund!P10 -> 32.34 | H39: =ROUND(F39-$B$5*Fund!T10,6) -> 0
A40: =Fund!B11 -> 45382 | B40: =$B$5*Fund!T10 -> 7.2431804 | C40: =$B$5*Fund!L11 -> 1.915 | D40: =-$B$5*Fund!O11 -> 0 | E40: =$B$5*(Fund!F11-Fund!J11-Fund!K11-Fund!AH11-Fund!AG11-Fund!AD11) -> 0.091 | F40: =B40+C40+D40+E40 -> 9.2491804 | G40: =$B$4-$B$5*Fund!P11 -> 30.425 | H40: =ROUND(F40-$B$5*Fund!T11,6) -> 0
A41: =Fund!B12 -> 45473 | B41: =$B$5*Fund!T11 -> 9.2491804 | C41: =$B$5*Fund!L12 -> 1.915 | D41: =-$B$5*Fund!O12 -> 0 | E41: =$B$5*(Fund!F12-Fund!J12-Fund!K12-Fund!AH12-Fund!AG12-Fund!AD12) -> 0.17574675 | F41: =B41+C41+D41+E41 -> 11.339927 | G41: =$B$4-$B$5*Fund!P12 -> 28.51 | H41: =ROUND(F41-$B$5*Fund!T12,6) -> 0
A42: =Fund!B13 -> 45565 | B42: =$B$5*Fund!T12 -> 11.339927 | C42: =$B$5*Fund!L13 -> 1.915 | D42: =-$B$5*Fund!O13 -> 0 | E42: =$B$5*(Fund!F13-Fund!J13-Fund!K13-Fund!AH13-Fund!AG13-Fund!AD13) -> 0.24127359 | F42: =B42+C42+D42+E42 -> 13.496201 | G42: =$B$4-$B$5*Fund!P13 -> 26.595 | H42: =ROUND(F42-$B$5*Fund!T13,6) -> 0
A43: =Fund!B14 -> 45657 | B43: =$B$5*Fund!T13 -> 13.496201 | C43: =$B$5*Fund!L14 -> 1.915 | D43: =-$B$5*Fund!O14 -> 0 | E43: =$B$5*(Fund!F14-Fund!J14-Fund!K14-Fund!AH14-Fund!AG14-Fund!AD14) -> 0.28490584 | F43: =B43+C43+D43+E43 -> 15.696107 | G43: =$B$4-$B$5*Fund!P14 -> 24.68 | H43: =ROUND(F43-$B$5*Fund!T14,6) -> 0
A44: =Fund!B15 -> 45747 | B44: =$B$5*Fund!T14 -> 15.696107 | C44: =$B$5*Fund!L15 -> 1.915 | D44: =-$B$5*Fund!O15 -> 0 | E44: =$B$5*(Fund!F15-Fund!J15-Fund!K15-Fund!AH15-Fund!AG15-Fund!AD15) -> 0.361664 | F44: =B44+C44+D44+E44 -> 17.972771 | G44: =$B$4-$B$5*Fund!P15 -> 22.765 | H44: =ROUND(F44-$B$5*Fund!T15,6) -> 0
A45: =Fund!B16 -> 45838 | B45: =$B$5*Fund!T15 -> 17.972771 | C45: =$B$5*Fund!L16 -> 1.915 | D45: =-$B$5*Fund!O16 -> 0 | E45: =$B$5*(Fund!F16-Fund!J16-Fund!K16-Fund!AH16-Fund!AG16-Fund!AD16) -> 0.44166493 | F45: =B45+C45+D45+E45 -> 20.329435 | G45: =$B$4-$B$5*Fund!P16 -> 20.85 | H45: =ROUND(F45-$B$5*Fund!T16,6) -> 0
...

Sheet Checks
A1: Model integrity checks
A2: All differences should be zero (tolerance 0.001).
A4: Check | B4: Difference | C4: What it tests
A5: Investor commitments sum to fund commitments | B5: =Inputs!B13-SUM(Inputs!B9:B12) -> 0 | C5: Commitment table adds up.
A6: Calls fully fund investments + fees + expenses in investment period | B6: =SUMPRODUCT(Fund!C7:C46*ABS(Fund!E7:E46+Fund!J7:J46+Fund!K7:K46-Fund!L7:L46)) -> 0 | C6: Commitment is never the binding constraint.
A7: Cumulative calls never exceed commitments | B7: =MAX(0,MAX(Fund!P7:P46)-Inputs!B13) -> 0 | C7: No over-calling.
A8: Portfolio fully realised by final quarter | B8: =Fund!I46 -> 0 | C8: Closing portfolio value in last quarter = 0.
A9: Investor NAV roll-forward identity (all quarters) | B9: =SUMPRODUCT(ABS(Fund!T7:T46-Fund!T6:T45-(Fund!L7:L46-Fund!O7:O46+Fund!F7:F46-Fund!J7:J46-Fund!K7:K46-Fund!AD7:AD46-Fund!AH7:AH46-Fund!AG7:AG46))) -> 3.6970427e-14 | C9: Change in NAV = calls - distributions + gains - fees - expenses - loan interest - loan fee - carry.
A10: Distributions + carry = distributions before carry | B10: =Fund!U46+Fund!R46-Fund!Q46 -> 0 | C10: Carry is deducted exactly once.
A11: Net IRR: NPV of flows at XIRR = 0 | B11: =ROUND(SUMPRODUCT(Fund!Z7:Z46/(1+Returns!B18)^((Fund!B7:B46-Fund!B7)/365)),4) -> 0 | C11: Independent test that the XIRR solution is right.
A12: Gross IRR: NPV of flows at XIRR = 0 | B12: =ROUND(SUMPRODUCT(Fund!AB7:AB46/(1+Returns!B26)^((Fund!B7:B46-Fund!B7)/365)),4) -> 0
A13: TVPI = DPI + RVPI at as-of date (Returns vs Fund time series) | B13: =ROUND(Returns!B17-INDEX(Fund!X7:X46,Returns!B5),6) -> 0
A14: LP statement: ending balance = share of fund NAV | B14: ='LP Statement'!B24 -> 0 | C14: Period statement ties to the fund.
A15: LP quarterly roll-forward ties to fund NAV (all quarters) | B15: =SUMPRODUCT(ABS('LP Statement'!H36:H75)) -> 0
A16: NAV loan fully repaid by final quarter | B16: =Fund!AJ46 -> 0 | C16: No debt left when the fund winds up.
A17: NAV loan drawn = repaid | B17: =Fund!AF48-Fund!AI48 -> 0 | C17: Total draws equal total repayments.
A18: Distributions never truncated by loan service | B18: =SUMPRODUCT(ABS(Fund!M7:M46-(Fund!C7:C46*Fund!H7:H46+(1-Fund!C7:C46)*(Fund!H7:H46-Fund!J7:J46-Fund!K7:K46)-Fund!AH7:AH46-Fund!AI7:AI46+Fund!AK7:AK46))) -> 0 | C18: Non-zero means exit proceeds were too small to pay interest and repayment: move the draw quarter or lower the LTV.
A19: Switch off: with-loan NAV equals no-loan NAV | B19: =IF(Inputs!B35=0,SUMPRODUCT(ABS(Fund!T7:T46-Fund!AS7:AS46)),0) -> 0 | C19: Confirms the loan layer is inert when off.
A21: OVERALL STATUS | B21: =IF(SUMPRODUCT(ABS(B5:B19))<0.001,"ALL CHECKS PASS","CHECK ERRORS") -> ALL CHECKS PASS
