Workbook

Sheet README
A1: Tesla, Inc. - Integrated 3-statement model and DCF
A2: Portfolio piece (Models 1 & 2). US$ millions, FY ends 31 December. Historicals FY2023A-FY2025A; forecast FY2026E-FY2030E. v2 built 5-Oct-2026 (adds Schedules sheet).
A4: Purpose | B4: A traceable, auditable model: income statement, balance sheet and cash flow are fully linked, and the DCF reads its cash flows straight from them. One switch (Assumptions!B3) runs Bear / Base / Bull.
A5: Sheet map | B5: Assumptions (all drivers) -> Schedules (bottom-up revenue, deferred revenue roll-forward, debt schedule) -> IS, BS, CF (statements) -> DCF (valuation, sensitivity, reverse DCF) -> Checks (ties to reported figures, balance) -> Sources.
A6: Colour code | B6: Blue = hard-coded input | Black = formula | Green = link from another sheet | Yellow fill = key assumption to challenge.
A7: How the statements link | B7: Revenue and margins (Assumptions) -> IS -> net income -> CF -> cash on BS. PP&E = opening + capex - D&A. Equity = opening + net income + SBC. Working-capital lines are driven by days / % of revenue and feed the CF. BS balance check is on the BS and Checks sheets.
A8: DCF method | B8: UFCF = NOPAT + D&A - capex - change in working capital, discounted at CAPM-based WACC (end-year), Gordon-growth terminal value, EV-to-equity bridge from the FY2025 balance sheet. SBC is not added back.
A9: Reading the result | B9: Base-case value per share (~$20) is far below the market price (~$359); even the Bull case is ~$35. At a 5.2% risk-free rate and beta ~1.85 the WACC is ~13.5%, and the market price only works if FY2030 free cash flow is ~30x the base case - the reverse DCF quantifies this. Caution: the implied terminal EV/EBITDA is only ~3-4x because FY2030E is still an investment year (capex/D&A ~1.2x, EBIT margin ~9%). Treat the absolute value as a conservative floor, and extend the forecast to 10 years with a fade to steady-state margins before relying on it.
A10: Known limitations | B10: (1) 5-year explicit period is short for a business still in heavy investment; terminal year capex/D&A is shown as a diagnostic. (2) Debt tranche split, rates and the deferred-revenue recognition rate are estimates built from Q1-2026 10-Q disclosures (not the full FY2025 10-K notes, which could not be downloaded) - verify against the 10-K debt and revenue notes. (2b) No explicit robotaxi / Optimus segment - only the Bull case proxies this through growth and margin. (3) Valuation date is the 31-Dec-2025 balance sheet, price is 28-Sep-2026 (9-month mismatch, not rolled forward). (4) FY2023-24 detail is limited to reported totals. (5) Share count differs by source (3.54bn diluted weighted / 3.75bn 10-K cover / 3.95bn market data) - verify against the latest 10-Q.
A11: Not investment advice | B11: Educational portfolio model built from public filings and illustrative assumptions.
A13: Key outputs (live)
A14: Active scenario | B14: =Assumptions!B4 -> Base
A15: WACC | B15: =DCF!B34 -> 0.13509497
A16: Enterprise value ($mm) | B16: =DCF!B42 -> 40678.174
A17: Implied value per share ($) | B17: =DCF!B55 -> 19.402829
A18: Current share price ($) | B18: =DCF!B56 -> 358.54
A19: Upside / (downside) | B19: =DCF!B57 -> -0.94588378
A20: Required / modelled FY2030E UFCF (reverse DCF) | B20: =DCF!B75 -> 32.174759
A21: Model integrity | B21: =Checks!B38 -> ALL CHECKS PASS

Sheet Assumptions
A1: Tesla, Inc. - Assumptions & scenario control
A2: Blue = hard-coded input | Black = formula | Green = link from another sheet | Yellow fill = key assumption. Forecast drivers are illustrative analyst assumptions, not company guidance unless noted.
A3: Scenario selector (1 = Bear, 2 = Base, 3 = Bull) | B3: 2 | J3: Change B3 to flow a scenario through revenue growth and segment gross margins for the whole model.
A4: Active scenario | B4: =CHOOSE(B3,"Bear","Base","Bull") -> Base
A6: ($mm unless stated) | B6: FY2023A | C6: FY2024A | D6: FY2025A | E6: FY2026E | F6: FY2027E | G6: FY2028E | H6: FY2029E | I6: FY2030E | J6: Source / note
A8: Automotive revenue growth (%) | J8: CROSS-CHECK ONLY: automotive revenue is now built bottom-up on Schedules (deliveries x price).
A9: Bear | E9: -0.04 | F9: 0 | G9: 0.02 | H9: 0.02 | I9: 0.02
A10: Base | E10: 0.02 | F10: 0.05 | G10: 0.06 | H10: 0.05 | I10: 0.04
A11: Bull | E11: 0.08 | F11: 0.12 | G11: 0.14 | H11: 0.12 | I11: 0.1
A12: Selected (feeds model) | C12: =IS!C6/IS!B6-1 -> -0.064900084 | D12: =IS!D6/IS!C6-1 -> -0.09788504 | E12: =CHOOSE($B$3,E9,E10,E11) -> 0.02 | F12: =CHOOSE($B$3,F9,F10,F11) -> 0.05 | G12: =CHOOSE($B$3,G9,G10,G11) -> 0.06 | H12: =CHOOSE($B$3,H9,H10,H11) -> 0.05 | I12: =CHOOSE($B$3,I9,I10,I11) -> 0.04
A14: Energy generation & storage revenue growth (%) | J14: CROSS-CHECK ONLY: energy revenue is now built bottom-up on Schedules (GWh x revenue per GWh).
A15: Bear | E15: 0.12 | F15: 0.1 | G15: 0.08 | H15: 0.06 | I15: 0.05
A16: Base | E16: 0.25 | F16: 0.22 | G16: 0.18 | H16: 0.15 | I16: 0.12
A17: Bull | E17: 0.35 | F17: 0.3 | G17: 0.25 | H17: 0.2 | I17: 0.15
A18: Selected (feeds model) | C18: =IS!C7/IS!B7-1 -> 0.67125104 | D18: =IS!D7/IS!C7-1 -> 0.26621059 | E18: =CHOOSE($B$3,E15,E16,E17) -> 0.25 | F18: =CHOOSE($B$3,F15,F16,F17) -> 0.22 | G18: =CHOOSE($B$3,G15,G16,G17) -> 0.18 | H18: =CHOOSE($B$3,H15,H16,H17) -> 0.15 | I18: =CHOOSE($B$3,I15,I16,I17) -> 0.12
A20: Services & other revenue growth (%) | J20: FY2025A: +19% (Supercharging, parts, insurance, FSD subscriptions).
A21: Bear | E21: 0.08 | F21: 0.07 | G21: 0.06 | H21: 0.05 | I21: 0.04
A22: Base | E22: 0.18 | F22: 0.16 | G22: 0.14 | H22: 0.12 | I22: 0.1
A23: Bull | E23: 0.25 | F23: 0.24 | G23: 0.22 | H23: 0.2 | I23: 0.18
A24: Selected (feeds model) | C24: =IS!C8/IS!B8-1 -> 0.26625796 | D24: =IS!D8/IS!C8-1 -> 0.18948168 | E24: =CHOOSE($B$3,E21,E22,E23) -> 0.18 | F24: =CHOOSE($B$3,F21,F22,F23) -> 0.16 | G24: =CHOOSE($B$3,G21,G22,G23) -> 0.14 | H24: =CHOOSE($B$3,H21,H22,H23) -> 0.12 | I24: =CHOOSE($B$3,I21,I22,I23) -> 0.1
A26: Automotive gross margin (%) | J26: FY2025A: 17.8% incl. regulatory credits (2.4% of auto rev.). Q4-25 auto GM 20.4%. OBBBA curtails credit programmes.
A27: Bear | E27: 0.16 | F27: 0.16 | G27: 0.165 | H27: 0.165 | I27: 0.17
A28: Base | E28: 0.18 | F28: 0.185 | G28: 0.19 | H28: 0.195 | I28: 0.2
A29: Bull | E29: 0.195 | F29: 0.21 | G29: 0.225 | H29: 0.24 | I29: 0.25
A30: Selected (feeds model) | D30: =1-IS!D11/IS!D6 -> 0.1777896 | E30: =CHOOSE($B$3,E27,E28,E29) -> 0.18 | F30: =CHOOSE($B$3,F27,F28,F29) -> 0.185 | G30: =CHOOSE($B$3,G27,G28,G29) -> 0.19 | H30: =CHOOSE($B$3,H27,H28,H29) -> 0.195 | I30: =CHOOSE($B$3,I27,I28,I29) -> 0.2
A32: Energy gross margin (%) | J32: FY2025A: 29.8% (computed from segment COGS).
A33: Bear | E33: 0.27 | F33: 0.26 | G33: 0.25 | H33: 0.25 | I33: 0.25
A34: Base | E34: 0.3 | F34: 0.3 | G34: 0.3 | H34: 0.295 | I34: 0.29
A35: Bull | E35: 0.31 | F35: 0.32 | G35: 0.32 | H35: 0.32 | I35: 0.32
A36: Selected (feeds model) | D36: =1-IS!D12/IS!D7 -> 0.29770574 | E36: =CHOOSE($B$3,E33,E34,E35) -> 0.3 | F36: =CHOOSE($B$3,F33,F34,F35) -> 0.3 | G36: =CHOOSE($B$3,G33,G34,G35) -> 0.3 | H36: =CHOOSE($B$3,H33,H34,H35) -> 0.295 | I36: =CHOOSE($B$3,I33,I34,I35) -> 0.29
A38: Services & other gross margin (%) | J38: FY2025A: 7.4% (computed). Bull assumes software/FSD-subscription mix lifts margin.
A39: Bear | E39: 0.07 | F39: 0.07 | G39: 0.07 | H39: 0.07 | I39: 0.07
A40: Base | E40: 0.08 | F40: 0.09 | G40: 0.1 | H40: 0.11 | I40: 0.12
A41: Bull | E41: 0.1 | F41: 0.13 | G41: 0.16 | H41: 0.19 | I41: 0.22
A42: Selected (feeds model) | D42: =1-IS!D13/IS!D8 -> 0.074301676 | E42: =CHOOSE($B$3,E39,E40,E41) -> 0.08 | F42: =CHOOSE($B$3,F39,F40,F41) -> 0.09 | G42: =CHOOSE($B$3,G39,G40,G41) -> 0.1 | H42: =CHOOSE($B$3,H39,H40,H41) -> 0.11 | I42: =CHOOSE($B$3,I39,I40,I41) -> 0.12
A44: Operating drivers
A45: R&D as % of revenue | D45: =IS!D17/IS!D9 -> 0.067607327 | E45: 0.072 | F45: 0.07 | G45: 0.068 | H45: 0.065 | I45: 0.063 | J45: FY2025A 6.8%. Elevated on AI compute, Optimus, Cybercab (mgmt: AI spend stays elevated through 2026).
A46: SG&A as % of revenue | D46: =IS!D18/IS!D9 -> 0.061522562 | E46: 0.06 | F46: 0.058 | G46: 0.056 | H46: 0.054 | I46: 0.052 | J46: FY2025A 6.2%. Modest operating leverage assumed.
A47: Restructuring & other ($mm) | D47: =IS!D19 -> 494 | E47: 0 | F47: 0 | G47: 0 | H47: 0 | I47: 0 | J47: Non-recurring; forecast at zero.
A48: Stock-based compensation as % of revenue | B48: =CF!B8/IS!B9 -> 0.018724231 | C48: =CF!C8/IS!C9 -> 0.020462688 | D48: =CF!D8/IS!D9 -> 0.029791093 | E48: 0.03 | F48: 0.03 | G48: 0.03 | H48: 0.03 | I48: 0.03 | J48: SBC is already embedded in R&D / SG&A %; this row only drives the cash-flow add-back and equity roll-forward.
...

Sheet Schedules
A1: Tesla, Inc. - Supporting schedules
A2: Bottom-up revenue build, deferred revenue roll-forward and debt schedule. Blue = input | Black = formula | Green = link. Volume/price scenarios follow Assumptions!B3.
A4: ($mm unless stated) | B4: FY2023A | C4: FY2024A | D4: FY2025A | E4: FY2026E | F4: FY2027E | G4: FY2028E | H4: FY2029E | I4: FY2030E | J4: Source / note
A6: 1. Automotive revenue - bottom-up (deliveries x revenue per delivery + regulatory credits)
A7: Delivery growth - Bear | E7: -0.05 | F7: -0.01 | G7: 0.01 | H7: 0.02 | I7: 0.02
A8: Delivery growth - Base | E8: 0.01 | F8: 0.04 | G8: 0.05 | H8: 0.04 | I8: 0.03
A9: Delivery growth - Bull | E9: 0.08 | F9: 0.1 | G9: 0.12 | H9: 0.1 | I9: 0.08
A10: Delivery growth - selected | E10: =CHOOSE(Assumptions!$B$3,E7,E8,E9) -> 0.01 | F10: =CHOOSE(Assumptions!$B$3,F7,F8,F9) -> 0.04 | G10: =CHOOSE(Assumptions!$B$3,G7,G8,G9) -> 0.05 | H10: =CHOOSE(Assumptions!$B$3,H7,H8,H9) -> 0.04 | I10: =CHOOSE(Assumptions!$B$3,I7,I8,I9) -> 0.03 | J10: FY2025A: -8.6% (1.64mm vs 1.79mm). Base: stabilisation then mid-single-digit volume growth. Analyst assumption.
A11: Core revenue per delivery growth - Bear | E11: 0 | F11: 0 | G11: 0.005 | H11: 0.005 | I11: 0.005
A12: Core revenue per delivery growth - Base | E12: 0.015 | F12: 0.01 | G12: 0.01 | H12: 0.01 | I12: 0.01
A13: Core revenue per delivery growth - Bull | E13: 0.02 | F13: 0.02 | G13: 0.015 | H13: 0.015 | I13: 0.015
A14: Core revenue per delivery growth - selected | E14: =CHOOSE(Assumptions!$B$3,E11,E12,E13) -> 0.015 | F14: =CHOOSE(Assumptions!$B$3,F11,F12,F13) -> 0.01 | G14: =CHOOSE(Assumptions!$B$3,G11,G12,G13) -> 0.01 | H14: =CHOOSE(Assumptions!$B$3,H11,H12,H13) -> 0.01 | I14: =CHOOSE(Assumptions!$B$3,I11,I12,I13) -> 0.01 | J14: Price/mix/FSD attach on vehicle sales and leasing. Analyst assumption.
A15: Vehicle deliveries (units) | B15: 1808581 | C15: 1789226 | D15: 1636129 | E15: =D15*(1+E10) -> 1652490.3 | F15: =E15*(1+F10) -> 1718589.9 | G15: =F15*(1+G10) -> 1804519.4 | H15: =G15*(1+H10) -> 1876700.2 | I15: =H15*(1+I10) -> 1933001.2 | J15: Tesla quarterly production & deliveries releases (FY23-FY25 totals).
A16: Core revenue per delivery ($, ex-regulatory credits) | D16: =D18*1000000/D15 -> 41276.085 | E16: =D16*(1+E14) -> 41895.226 | F16: =E16*(1+F14) -> 42314.179 | G16: =F16*(1+G14) -> 42737.321 | H16: =G16*(1+H14) -> 43164.694 | I16: =H16*(1+I14) -> 43596.341 | J16: FY2025A derived: (automotive revenue - credits) / deliveries. Blended figure incl. leasing and used-vehicle/other automotive sales.
A17: Regulatory credit revenue ($mm) | D17: 1993 | E17: 1500 | F17: 1100 | G17: 800 | H17: 600 | I17: 400 | J17: FY2025A $1,993mm. Forecast runs down as US credit programmes are curtailed - analyst assumption.
A18: Core vehicle revenue ($mm) | D18: =IS!D6-D17 -> 67533 | E18: =E15*E16/1000000 -> 69231.455 | F18: =F15*F16/1000000 -> 72720.72 | G18: =G15*G16/1000000 -> 77120.324 | H18: =H15*H16/1000000 -> 81007.188 | I18: =I15*I16/1000000 -> 84271.778
A19: Automotive revenue - bottom-up ($mm) | B19: =IS!B6 -> 82419 | C19: =IS!C6 -> 77070 | D19: =IS!D6 -> 69526 | E19: =E18+E17 -> 70731.455 | F19: =F18+F17 -> 73820.72 | G19: =G18+G17 -> 77920.324 | H19: =H18+H17 -> 81607.188 | I19: =I18+I17 -> 84671.778
A20: Memo: top-down automotive revenue (prior growth-rate method) | E20: =IS!D6*(1+Assumptions!E12) -> 70916.52 | F20: =E20*(1+Assumptions!F12) -> 74462.346 | G20: =F20*(1+Assumptions!G12) -> 78930.087 | H20: =G20*(1+Assumptions!H12) -> 82876.591 | I20: =H20*(1+Assumptions!I12) -> 86191.655 | J20: Cross-check only. Uses the selected growth rows on Assumptions (no longer drive the model).
A21: Bottom-up vs top-down (%) | E21: =E19/E20-1 -> -0.0026096183 | F21: =F19/F20-1 -> -0.0086167809 | G21: =G19/G20-1 -> -0.012793131 | H21: =H19/H20-1 -> -0.015316785 | I21: =I19/I20-1 -> -0.01763369
A23: 2. Energy storage revenue - bottom-up (GWh deployed x revenue per GWh)
A24: GWh deployed growth - Bear | E24: 0.15 | F24: 0.12 | G24: 0.1 | H24: 0.08 | I24: 0.06
A25: GWh deployed growth - Base | E25: 0.3 | F25: 0.25 | G25: 0.2 | H25: 0.15 | I25: 0.12
A26: GWh deployed growth - Bull | E26: 0.4 | F26: 0.32 | G26: 0.26 | H26: 0.2 | I26: 0.15
A27: GWh deployed growth - selected | E27: =CHOOSE(Assumptions!$B$3,E24,E25,E26) -> 0.3 | F27: =CHOOSE(Assumptions!$B$3,F24,F25,F26) -> 0.25 | G27: =CHOOSE(Assumptions!$B$3,G24,G25,G26) -> 0.2 | H27: =CHOOSE(Assumptions!$B$3,H24,H25,H26) -> 0.15 | I27: =CHOOSE(Assumptions!$B$3,I24,I25,I26) -> 0.12 | J27: FY2025A: +49% (46.7 GWh). Base fades as the base grows. Analyst assumption.
A28: Revenue per GWh change - Bear | E28: -0.1 | F28: -0.06 | G28: -0.04 | H28: -0.03 | I28: -0.03
A29: Revenue per GWh change - Base | E29: -0.06 | F29: -0.04 | G29: -0.03 | H29: -0.02 | I29: -0.02
A30: Revenue per GWh change - Bull | E30: -0.04 | F30: -0.02 | G30: -0.01 | H30: 0 | I30: 0
A31: Revenue per GWh change - selected | E31: =CHOOSE(Assumptions!$B$3,E28,E29,E30) -> -0.06 | F31: =CHOOSE(Assumptions!$B$3,F28,F29,F30) -> -0.04 | G31: =CHOOSE(Assumptions!$B$3,G28,G29,G30) -> -0.03 | H31: =CHOOSE(Assumptions!$B$3,H28,H29,H30) -> -0.02 | I31: =CHOOSE(Assumptions!$B$3,I28,I29,I30) -> -0.02 | J31: Revenue/GWh fell 15% in FY2025A (storage pricing competition, mix). Revenue is recognised on project timing, not on deployment date.
A32: Storage deployed (GWh) | B32: 14.7 | C32: 31.4 | D32: 46.7 | E32: =D32*(1+E27) -> 60.71 | F32: =E32*(1+F27) -> 75.8875 | G32: =F32*(1+G27) -> 91.065 | H32: =G32*(1+H27) -> 104.72475 | I32: =H32*(1+I27) -> 117.29172 | J32: Tesla production & deliveries releases.
A33: Revenue per GWh deployed ($mm) | B33: =IS!B7/B32 -> 410.54422 | C33: =IS!C7/C32 -> 321.21019 | D33: =IS!D7/D32 -> 273.46895 | E33: =D33*(1+E31) -> 257.06081 | F33: =E33*(1+F31) -> 246.77838 | G33: =F33*(1+G31) -> 239.37503 | H33: =G33*(1+H31) -> 234.58753 | I33: =H33*(1+I31) -> 229.89578 | J33: Historical = energy segment revenue / GWh (includes solar and services, so it overstates pure storage price).
A34: Energy revenue - bottom-up ($mm) | B34: =IS!B7 -> 6035 | C34: =IS!C7 -> 10086 | D34: =IS!D7 -> 12771 | E34: =E32*E33 -> 15606.162 | F34: =F32*F33 -> 18727.394 | G34: =G32*G33 -> 21798.687 | H34: =H32*H33 -> 24567.12 | I34: =I32*I33 -> 26964.871
A35: Memo: top-down energy revenue (prior growth-rate method) | E35: =IS!D7*(1+Assumptions!E18) -> 15963.75 | F35: =E35*(1+Assumptions!F18) -> 19475.775 | G35: =F35*(1+Assumptions!G18) -> 22981.414 | H35: =G35*(1+Assumptions!H18) -> 26428.627 | I35: =H35*(1+Assumptions!I18) -> 29600.062
A36: Bottom-up vs top-down (%) | E36: =E34/E35-1 -> -0.0224 | F36: =F34/F35-1 -> -0.03842623 | G36: =G34/G35-1 -> -0.051464518 | H36: =H34/H35-1 -> -0.070435228 | I36: =I34/I35-1 -> -0.089026523 | J36: Services & other revenue remains top-down (Assumptions growth rate).
A38: 3. Deferred revenue roll-forward (opening + billings - revenue recognised = closing)
A39: Revenue recognised, % of opening balance | E39: 0.55 | F39: 0.55 | G39: 0.55 | H39: 0.55 | I39: 0.55 | J39: ESTIMATE. Q1-26 10-Q: c.$1.0bn recognised from the 31-Dec-25 balance in one quarter (auto $218mm + energy $781mm, as read from the filing excerpt) -> roughly 55% annualised. Verify against the 10-K note.
A40: Billings in advance, % of total revenue | E40: 0.042 | F40: 0.042 | G40: 0.042 | H40: 0.042 | I40: 0.042 | J40: ESTIMATE, calibrated so the balance stays near 7% of revenue (FY2025A 7.4%). Cash billed before delivery: FSD/connectivity, extended service, energy project milestones.
A41: Opening deferred revenue | E41: =BS!D18 -> 7055 | F41: =E44 -> 7421.9167 | G41: =F44 -> 7947.228 | H41: =G44 -> 8585.644 | I41: =H44 -> 9242.5969
A42: Plus: billings in advance | E42: =E40*IS!E9 -> 4247.1667 | F42: =F40*IS!F9 -> 4607.3655 | G42: =G40*IS!G9 -> 5009.3914 | H42: =H40*IS!H9 -> 5379.0571 | I42: =I40*IS!I9 -> 5700.449
A43: Less: revenue recognised from deferred revenue | E43: =E41*E39 -> 3880.25 | F43: =F41*F39 -> 4082.0542 | G43: =G41*G39 -> 4370.9754 | H43: =H41*H39 -> 4722.1042 | I43: =I41*I39 -> 5083.4283
A44: Closing deferred revenue (-> balance sheet) | C44: =BS!C18 -> 6485 | D44: =BS!D18 -> 7055 | E44: =E41+E42-E43 -> 7421.9167 | F44: =F41+F42-F43 -> 7947.228 | G44: =G41+G42-G43 -> 8585.644 | H44: =H41+H42-H43 -> 9242.5969 | I44: =I41+I42-I43 -> 9859.6176
...

Sheet IS
A1: Tesla, Inc. - Income statement
A2: US$ millions, fiscal year ending 31 December. FY2025A = sum of four reported quarters (ties to 10-K totals).
A5: ($mm unless stated) | B5: FY2023A | C5: FY2024A | D5: FY2025A | E5: FY2026E | F5: FY2027E | G5: FY2028E | H5: FY2029E | I5: FY2030E | J5: Source / note
A6: Automotive revenue | B6: 82419 | C6: 77070 | D6: 69526 | E6: =Schedules!E19 -> 70731.455 | F6: =Schedules!F19 -> 73820.72 | G6: =Schedules!G19 -> 77920.324 | H6: =Schedules!H19 -> 81607.188 | I6: =Schedules!I19 -> 84671.778 | J6: Tesla Q4/FY2025 Update (8-K Ex. 99.1) - Financial Summary (annual); incl. sales, regulatory credits ($1,993mm FY25) and leasing. Forecast = bottom-up build on Schedules (deliveries x revenue per delivery + credits).
A7: Energy generation & storage revenue | B7: 6035 | C7: 10086 | D7: 12771 | E7: =Schedules!E34 -> 15606.162 | F7: =Schedules!F34 -> 18727.394 | G7: =Schedules!G34 -> 21798.687 | H7: =Schedules!H34 -> 24567.12 | I7: =Schedules!I34 -> 26964.871 | J7: Tesla Q4/FY2025 Update (8-K Ex. 99.1) - Financial Summary (annual). Forecast = bottom-up build on Schedules (GWh deployed x revenue per GWh).
A8: Services & other revenue | B8: 8319 | C8: 10534 | D8: 12530 | E8: =D8*(1+Assumptions!E24) -> 14785.4 | F8: =E8*(1+Assumptions!F24) -> 17151.064 | G8: =F8*(1+Assumptions!G24) -> 19552.213 | H8: =G8*(1+Assumptions!H24) -> 21898.479 | I8: =H8*(1+Assumptions!I24) -> 24088.326 | J8: Tesla Q4/FY2025 Update (8-K Ex. 99.1) - Financial Summary (annual)
A9: Total revenues | B9: =SUM(B6:B8) -> 96773 | C9: =SUM(C6:C8) -> 97690 | D9: =SUM(D6:D8) -> 94827 | E9: =SUM(E6:E8) -> 101123.02 | F9: =SUM(F6:F8) -> 109699.18 | G9: =SUM(G6:G8) -> 119271.22 | H9: =SUM(H6:H8) -> 128072.79 | I9: =SUM(I6:I8) -> 135724.98 | J9: Ties to reported: 96,773 / 97,690 / 94,827 (see Checks).
A11: Cost of revenues - Automotive | D11: 57165 | E11: =E6*(1-Assumptions!E30) -> 57999.793 | F11: =F6*(1-Assumptions!F30) -> 60163.887 | G11: =G6*(1-Assumptions!G30) -> 63115.462 | H11: =H6*(1-Assumptions!H30) -> 65693.786 | I11: =I6*(1-Assumptions!I30) -> 67737.422 | J11: FY25A = automotive sales COGS 56,267 + leasing COGS 898 (sum of quarters, p.28). Segment COGS not sourced for FY23-24.
A12: Cost of revenues - Energy | D12: 8969 | E12: =E7*(1-Assumptions!E36) -> 10924.313 | F12: =F7*(1-Assumptions!F36) -> 13109.176 | G12: =G7*(1-Assumptions!G36) -> 15259.081 | H12: =H7*(1-Assumptions!H36) -> 17319.82 | I12: =I7*(1-Assumptions!I36) -> 19145.059 | J12: Sum of Q1-Q4 2025 statements of operations, Tesla Q4/FY2025 Update p.28
A13: Cost of revenues - Services & other | D13: 11599 | E13: =E8*(1-Assumptions!E42) -> 13602.568 | F13: =F8*(1-Assumptions!F42) -> 15607.468 | G13: =G8*(1-Assumptions!G42) -> 17596.992 | H13: =H8*(1-Assumptions!H42) -> 19489.646 | I13: =I8*(1-Assumptions!I42) -> 21197.727 | J13: Sum of Q1-Q4 2025 statements of operations, Tesla Q4/FY2025 Update p.28
A14: Total cost of revenues | B14: 79113 | C14: 80240 | D14: =SUM(D11:D13) -> 77733 | E14: =SUM(E11:E13) -> 82526.674 | F14: =SUM(F11:F13) -> 88880.531 | G14: =SUM(G11:G13) -> 95971.535 | H14: =SUM(H11:H13) -> 102503.25 | I14: =SUM(I11:I13) -> 108080.21 | J14: FY23-24 derived: reported revenue less reported gross profit (17,660 / 17,450). FY25 = 77,733 (sum of segments).
A15: Gross profit | B15: =B9-B14 -> 17660 | C15: =C9-C14 -> 17450 | D15: =D9-D14 -> 17094 | E15: =E9-E14 -> 18596.342 | F15: =F9-F14 -> 20818.647 | G15: =G9-G14 -> 23299.689 | H15: =H9-H14 -> 25569.535 | I15: =I9-I14 -> 27644.767
A17: Research & development | D17: 6411 | E17: =E9*Assumptions!E45 -> 7280.8572 | F17: =F9*Assumptions!F45 -> 7678.9425 | G17: =G9*Assumptions!G45 -> 8110.4432 | H17: =H9*Assumptions!H45 -> 8324.7312 | I17: =I9*Assumptions!I45 -> 8550.6735 | J17: Sum of Q1-Q4 2025 statements of operations, Tesla Q4/FY2025 Update p.28
A18: Selling, general & administrative | D18: 5834 | E18: =E9*Assumptions!E46 -> 6067.381 | F18: =F9*Assumptions!F46 -> 6362.5524 | G18: =G9*Assumptions!G46 -> 6679.1885 | H18: =H9*Assumptions!H46 -> 6915.9305 | I18: =I9*Assumptions!I46 -> 7057.6987 | J18: Sum of Q1-Q4 2025 statements of operations, Tesla Q4/FY2025 Update p.28
A19: Restructuring & other | D19: 494 | E19: =Assumptions!E47 -> 0 | F19: =Assumptions!F47 -> 0 | G19: =Assumptions!G47 -> 0 | H19: =Assumptions!H47 -> 0 | I19: =Assumptions!I47 -> 0 | J19: Sum of Q1-Q4 2025 statements of operations, Tesla Q4/FY2025 Update p.28
A20: Total operating expenses | B20: 8769 | C20: 10374 | D20: =SUM(D17:D19) -> 12739 | E20: =SUM(E17:E19) -> 13348.238 | F20: =SUM(F17:F19) -> 14041.495 | G20: =SUM(G17:G19) -> 14789.632 | H20: =SUM(H17:H19) -> 15240.662 | I20: =SUM(I17:I19) -> 15608.372 | J20: FY23-24 shown in total only (line split not sourced). SBC and D&A are embedded in COGS and opex.
A21: Operating income (EBIT) | B21: =B15-B20 -> 8891 | C21: =C15-C20 -> 7076 | D21: =D15-D20 -> 4355 | E21: =E15-E20 -> 5248.1043 | F21: =F15-F20 -> 6777.1525 | G21: =G15-G20 -> 8510.0572 | H21: =H15-H20 -> 10328.873 | I21: =I15-I20 -> 12036.395 | J21: Ties to reported: 8,891 / 7,076 / 4,355.
A23: Interest income | D23: 1680 | E23: =Assumptions!E63*BS!D6 -> 1762.36 | F23: =Assumptions!F63*BS!E6 -> 1548.5676 | G23: =Assumptions!G63*BS!F6 -> 1590.9757 | H23: =Assumptions!H63*BS!G6 -> 1852.0919 | I23: =Assumptions!I63*BS!H6 -> 2273.7156 | J23: FY25A sum of quarters. Forecast = yield x opening cash & investments.
A24: Interest expense | B24: 156 | C24: 350 | D24: 338 | E24: =Schedules!E101 -> 357.62956 | F24: =Schedules!F101 -> 371.16312 | G24: =Schedules!G101 -> 381.54549 | H24: =Schedules!H101 -> 390.16543 | I24: =Schedules!I101 -> 397.77841 | J24: Forecast = sum of interest by debt tranche (Schedules). Shown as positive number and subtracted. Source: EBITDA reconciliation, Tesla Q4/FY2025 Update p.32.
A25: Other income / (expense), net | D25: -419 | E25: 0 | F25: 0 | G25: 0 | H25: 0 | I25: 0 | J25: FY25A includes bitcoin mark-to-market and FX losses on intercompany borrowings. Forecast zero.
A26: Interest income, other & NCI, net (derived, FY23-24 only) | B26: 1261 | C26: 2202 | J26: FY23-24 balancing item = NI to common + tax - EBIT + interest expense (line detail not sourced); FY23 also includes 5.9bn tax release in tax line.
A27: Income before income taxes | B27: =B21+B23-B24+B25+B26 -> 9996 | C27: =C21+C23-C24+C25+C26 -> 8928 | D27: =D21+D23-D24+D25+D26 -> 5278 | E27: =E21+E23-E24+E25+E26 -> 6652.8347 | F27: =F21+F23-F24+F25+F26 -> 7954.5569 | G27: =G21+G23-G24+G25+G26 -> 9719.4874 | H27: =H21+H23-H24+H25+H26 -> 11790.8 | I27: =I21+I23-I24+I25+I26 -> 13912.332 | J27: FY25A ties to 5,278 (sum of quarters). FY23-24 approximate (NCI embedded).
A28: Provision for / (benefit from) income taxes | B28: -5001 | C28: 1837 | D28: 1423 | E28: =E27*Assumptions!E65 -> 1663.2087 | F28: =F27*Assumptions!F65 -> 1988.6392 | G28: =G27*Assumptions!G65 -> 2429.8718 | H28: =H27*Assumptions!H65 -> 2947.6999 | I28: =I27*Assumptions!I65 -> 3478.0831 | J28: Source: EBITDA reconciliation, Tesla Q4/FY2025 Update p.32.
A29: Net income | B29: =B27-B28 -> 14997 | C29: =C27-C28 -> 7091 | D29: =D27-D28 -> 3855 | E29: =E27-E28 -> 4989.626 | F29: =F27-F28 -> 5965.9177 | G29: =G27-G28 -> 7289.6155 | H29: =H27-H28 -> 8843.0997 | I29: =I27-I28 -> 10434.249
A30: Less: net income attributable to NCI | D30: 61 | E30: =Assumptions!E66 -> 60 | F30: =Assumptions!F66 -> 60 | G30: =Assumptions!G66 -> 60 | H30: =Assumptions!H66 -> 60 | I30: =Assumptions!I66 -> 60 | J30: FY25A: 11+18+16+16 (quarterly).
A31: Net income attributable to common stockholders | B31: =B29-B30 -> 14997 | C31: =C29-C30 -> 7091 | D31: =D29-D30 -> 3794 | E31: =E29-E30 -> 4929.626 | F31: =F29-F30 -> 5905.9177 | G31: =G29-G30 -> 7229.6155 | H31: =H29-H30 -> 8783.0997 | I31: =I29-I30 -> 10374.249 | J31: Ties to reported GAAP: 14,997 / 7,091 / 3,794.
A33: Memo / ratios
A34: Revenue growth | C34: =C9/B9-1 -> 0.0094757835 | D34: =D9/C9-1 -> -0.029306992 | E34: =E9/D9-1 -> 0.066394771 | F34: =F9/E9-1 -> 0.084809196 | G34: =G9/F9-1 -> 0.087257219 | H34: =H9/G9-1 -> 0.073794524 | I34: =I9/H9-1 -> 0.059748746
A35: Gross margin | B35: =B15/B9 -> 0.18248892 | C35: =C15/C9 -> 0.17862627 | D35: =D15/D9 -> 0.18026511 | E35: =E15/E9 -> 0.18389822 | F35: =F15/F9 -> 0.18977943 | G35: =G15/G9 -> 0.19535046 | H35: =H15/H9 -> 0.19964846 | I35: =I15/I9 -> 0.20368224
A36: Operating margin | B36: =B21/B9 -> 0.0918748 | C36: =C21/C9 -> 0.072433207 | D36: =D21/D9 -> 0.045925738 | E36: =E21/E9 -> 0.051898217 | F36: =F21/F9 -> 0.061779428 | G36: =G21/G9 -> 0.071350464 | H36: =H21/H9 -> 0.080648461 | I36: =I21/I9 -> 0.088682243
A37: Depreciation, amortisation & impairment | B37: =CF!B7 -> 4667 | C37: =CF!C7 -> 5368 | D37: =CF!D7 -> 6148 | E37: =CF!E7 -> 6520.67 | F37: =CF!F7 -> 8367.9113 | G37: =CF!G7 -> 9561.8257 | H37: =CF!H7 -> 10256.946 | I37: =CF!I7 -> 10671.736
A38: EBITDA (EBIT + D&A) | B38: =B21+B37 -> 13558 | C38: =C21+C37 -> 12444 | D38: =D21+D37 -> 10503 | E38: =E21+E37 -> 11768.774 | F38: =F21+F37 -> 15145.064 | G38: =G21+G37 -> 18071.883 | H38: =H21+H37 -> 20585.819 | I38: =I21+I37 -> 22708.132 | J38: Tesla's reported "Adjusted EBITDA" (14,596 FY25) also adds back SBC; this line does not.
A39: EBITDA margin | B39: =B38/B9 -> 0.14010106 | C39: =C38/C9 -> 0.12738254 | D39: =D38/D9 -> 0.11075959 | E39: =E38/E9 -> 0.11638077 | F39: =F38/F9 -> 0.13805996 | G39: =G38/G9 -> 0.15151922 | H39: =H38/H9 -> 0.16073531 | I39: =I38/I9 -> 0.1673099
A40: Effective tax rate | B40: =B28/B27 -> -0.50030012 | C40: =C28/C27 -> 0.20575717 | D40: =D28/D27 -> 0.2696097 | E40: =E28/E27 -> 0.25 | F40: =F28/F27 -> 0.25 | G40: =G28/G27 -> 0.25 | H40: =H28/H27 -> 0.25 | I40: =I28/I27 -> 0.25

Sheet BS
A1: Tesla, Inc. - Balance sheet
A2: US$ millions, 31 December. Line items grouped for modelling; groupings shown in notes. FY2023A not sourced.
A5: ($mm unless stated) | B5: FY2023A | C5: FY2024A | D5: FY2025A | E5: FY2026E | F5: FY2027E | G5: FY2028E | H5: FY2029E | I5: FY2030E | J5: Source / note
A6: Cash, cash equivalents & investments | C6: 36563 | D6: 44059 | E6: =D6+CF!E19 -> 38714.19 | F6: =E6+CF!F19 -> 39774.391 | G6: =F6+CF!G19 -> 46302.297 | H6: =G6+CF!H19 -> 56842.89 | I6: =H6+CF!I19 -> 70705.032 | J6: Tesla 10-K FY2025 / Q4-25 Update balance sheet (p.29). FY25: cash 16,513 + ST investments 27,546. Forecast = opening + net change in cash (CF).
A7: Accounts receivable, net | C7: 4418 | D7: 4576 | E7: =Assumptions!E53*IS!E9/365 -> 4848.3638 | F7: =Assumptions!F53*IS!F9/365 -> 5259.5497 | G7: =Assumptions!G53*IS!G9/365 -> 5718.4833 | H7: =Assumptions!H53*IS!H9/365 -> 6140.4761 | I7: =Assumptions!I53*IS!I9/365 -> 6507.3618 | J7: Tesla 10-K FY2025 / Q4-25 Update balance sheet (p.29)
A8: Inventory | C8: 12017 | D8: 12392 | E8: =Assumptions!E54*IS!E14/365 -> 13113.828 | F8: =Assumptions!F54*IS!F14/365 -> 14123.482 | G8: =Assumptions!G54*IS!G14/365 -> 15250.271 | H8: =Assumptions!H54*IS!H14/365 -> 16288.188 | I8: =Assumptions!I54*IS!I14/365 -> 17174.389 | J8: Tesla 10-K FY2025 / Q4-25 Update balance sheet (p.29)
A9: Prepaid expenses & other current assets | C9: 5362 | D9: 7615 | E9: =Assumptions!E55*IS!E9 -> 8089.8414 | F9: =Assumptions!F55*IS!F9 -> 8775.9343 | G9: =Assumptions!G55*IS!G9 -> 9541.6979 | H9: =Assumptions!H55*IS!H9 -> 10245.823 | I9: =Assumptions!I55*IS!I9 -> 10857.998 | J9: Tesla 10-K FY2025 / Q4-25 Update balance sheet (p.29)
A10: Total current assets | C10: =SUM(C6:C9) -> 58360 | D10: =SUM(D6:D9) -> 68642 | E10: =SUM(E6:E9) -> 64766.223 | F10: =SUM(F6:F9) -> 67933.357 | G10: =SUM(G6:G9) -> 76812.749 | H10: =SUM(H6:H9) -> 89517.377 | I10: =SUM(I6:I9) -> 105244.78
A11: PP&E and operating assets, net | C11: 46341 | D11: 50159 | E11: =D11-CF!E13-CF!E7 -> 64368.548 | F11: =E11-CF!F13-CF!F7 -> 73552.506 | G11: =F11-CF!G13-CF!G7 -> 78899.583 | H11: =G11-CF!H13-CF!H7 -> 82090.28 | I11: =H11-CF!I13-CF!I7 -> 83633.791 | J11: Forecast = opening + capex - D&A.
A12: Digital assets | C12: 1076 | D12: 1008 | E12: =D12 -> 1008 | F12: =E12 -> 1008 | G12: =F12 -> 1008 | H12: =G12 -> 1008 | I12: =H12 -> 1008 | J12: Tesla 10-K FY2025 / Q4-25 Update balance sheet (p.29). Treated as non-operating asset in the EV bridge.
A13: Other non-current assets | C13: 16293 | D13: 17997 | E13: =D13+Assumptions!E60 -> 17997 | F13: =E13+Assumptions!F60 -> 17997 | G13: =F13+Assumptions!G60 -> 17997 | H13: =G13+Assumptions!H60 -> 17997 | I13: =H13+Assumptions!I60 -> 17997 | J13: Operating lease ROU assets + deferred tax assets + other: 6,027 + 6,925 + 5,045 (FY25).
A14: Total assets | C14: =C10+C11+C12+C13 -> 122070 | D14: =D10+D11+D12+D13 -> 137806 | E14: =E10+E11+E12+E13 -> 148139.77 | F14: =F10+F11+F12+F13 -> 160490.86 | G14: =G10+G11+G12+G13 -> 174717.33 | H14: =H10+H11+H12+H13 -> 190612.66 | I14: =I10+I11+I12+I13 -> 207883.57 | J14: Ties to reported: 122,070 (FY24) / 137,806 (FY25).
A16: Accounts payable | C16: 12474 | D16: 13371 | E16: =Assumptions!E56*IS!E14/365 -> 14131.28 | F16: =Assumptions!F56*IS!F14/365 -> 15219.269 | G16: =Assumptions!G56*IS!G14/365 -> 16433.482 | H16: =Assumptions!H56*IS!H14/365 -> 17551.927 | I16: =Assumptions!I56*IS!I14/365 -> 18506.885 | J16: Tesla 10-K FY2025 / Q4-25 Update balance sheet (p.29)
A17: Accrued liabilities & other | C17: 10723 | D17: 13279 | E17: =Assumptions!E57*IS!E9 -> 14157.222 | F17: =Assumptions!F57*IS!F9 -> 15357.885 | G17: =Assumptions!G57*IS!G9 -> 16697.971 | H17: =Assumptions!H57*IS!H9 -> 17930.19 | I17: =Assumptions!I57*IS!I9 -> 19001.497 | J17: Tesla 10-K FY2025 / Q4-25 Update balance sheet (p.29)
A18: Deferred revenue (current + non-current) | C18: 6485 | D18: 7055 | E18: =Schedules!E44 -> 7421.9167 | F18: =Schedules!F44 -> 7947.228 | G18: =Schedules!G44 -> 8585.644 | H18: =Schedules!H44 -> 9242.5969 | I18: =Schedules!I44 -> 9859.6176 | J18: FY25: 3,424 + 3,631.
A19: Debt & finance leases (current + non-current) | C19: 8213 | D19: 8376 | E19: =Schedules!E99 -> 8681.0358 | F19: =Schedules!F99 -> 8961.2712 | G19: =Schedules!G99 -> 9127.2729 | H19: =Schedules!H99 -> 9329.6984 | I19: =Schedules!I99 -> 9451.3296 | J19: FY25: 1,640 + 6,736. Almost all non-recourse (vehicle/energy financing).
A20: Other long-term liabilities | C20: 10495 | D20: 12860 | E20: =D20+Assumptions!E59 -> 12860 | F20: =E20+Assumptions!F59 -> 12860 | G20: =F20+Assumptions!G59 -> 12860 | H20: =G20+Assumptions!H59 -> 12860 | I20: =H20+Assumptions!I59 -> 12860 | J20: Tesla 10-K FY2025 / Q4-25 Update balance sheet (p.29)
A21: Total liabilities | C21: =SUM(C16:C20) -> 48390 | D21: =SUM(D16:D20) -> 54941 | E21: =SUM(E16:E20) -> 57251.455 | F21: =SUM(F16:F20) -> 60345.653 | G21: =SUM(G16:G20) -> 63704.37 | H21: =SUM(H16:H20) -> 66914.412 | I21: =SUM(I16:I20) -> 69679.329 | J21: Ties to reported: 48,390 (FY24) / 54,941 (FY25).
A23: Total stockholders' equity | C23: 72913 | D23: 82137 | E23: =D23+IS!E31+CF!E8 -> 90100.317 | F23: =E23+IS!F31+CF!F8 -> 99297.21 | G23: =F23+IS!G31+CF!G8 -> 110104.96 | H23: =G23+IS!H31+CF!H8 -> 122730.25 | I23: =H23+IS!I31+CF!I8 -> 137176.24 | J23: Forecast = opening + net income to common + SBC (credited to APIC). No buybacks or dividends.
A24: Non-controlling & redeemable NCI | C24: 767 | D24: 728 | E24: =D24+IS!E30 -> 788 | F24: =E24+IS!F30 -> 848 | G24: =F24+IS!G30 -> 908 | H24: =G24+IS!H30 -> 968 | I24: =H24+IS!I30 -> 1028 | J24: FY25: 670 + 58 redeemable; FY24: 704 + 63.
A25: Total equity | C25: =C23+C24 -> 73680 | D25: =D23+D24 -> 82865 | E25: =E23+E24 -> 90888.317 | F25: =F23+F24 -> 100145.21 | G25: =G23+G24 -> 111012.96 | H25: =H23+H24 -> 123698.25 | I25: =I23+I24 -> 138204.24
A26: Total liabilities & equity | C26: =C21+C25 -> 122070 | D26: =D21+D25 -> 137806 | E26: =E21+E25 -> 148139.77 | F26: =F21+F25 -> 160490.86 | G26: =G21+G25 -> 174717.33 | H26: =H21+H25 -> 190612.66 | I26: =I21+I25 -> 207883.57
A28: Balance check (assets - liabilities & equity) - must be zero | C28: =ROUND(C14-C26,3) -> 0 | D28: =ROUND(D14-D26,3) -> 0 | E28: =ROUND(E14-E26,3) -> 0 | F28: =ROUND(F14-F26,3) -> 0 | G28: =ROUND(G14-G26,3) -> 0 | H28: =ROUND(H14-H26,3) -> 0 | I28: =ROUND(I14-I26,3) -> 0

Sheet CF
A1: Tesla, Inc. - Cash flow statement
A2: US$ millions. FY2025A = sum of four reported quarters. FY2023-24 only headline items sourced.
A5: ($mm unless stated) | B5: FY2023A | C5: FY2024A | D5: FY2025A | E5: FY2026E | F5: FY2027E | G5: FY2028E | H5: FY2029E | I5: FY2030E | J5: Source / note
A6: Net income (incl. NCI) | D6: =IS!D29 -> 3855 | E6: =IS!E29 -> 4989.626 | F6: =IS!F29 -> 5965.9177 | G6: =IS!G29 -> 7289.6155 | H6: =IS!H29 -> 8843.0997 | I6: =IS!I29 -> 10434.249 | J6: FY25A 3,855 ties to sum of quarterly net income (420+1,190+1,389+856).
A7: Depreciation, amortisation & impairment | B7: 4667 | C7: 5368 | D7: 6148 | E7: =Assumptions!E49*BS!D11 -> 6520.67 | F7: =Assumptions!F49*BS!E11 -> 8367.9113 | G7: =Assumptions!G49*BS!F11 -> 9561.8257 | H7: =Assumptions!H49*BS!G11 -> 10256.946 | I7: =Assumptions!I49*BS!H11 -> 10671.736 | J7: Source: EBITDA reconciliation p.32; forecast = rate x opening PP&E.
A8: Stock-based compensation | B8: 1812 | C8: 1999 | D8: 2825 | E8: =Assumptions!E48*IS!E9 -> 3033.6905 | F8: =Assumptions!F48*IS!F9 -> 3290.9754 | G8: =Assumptions!G48*IS!G9 -> 3578.1367 | H8: =Assumptions!H48*IS!H9 -> 3842.1836 | I8: =Assumptions!I48*IS!I9 -> 4071.7493 | J8: Source: EBITDA reconciliation p.32.
A9: Other non-cash items | D9: 1277 | E9: 0 | F9: 0 | G9: 0 | H9: 0 | I9: 0 | J9: FY25A: deferred taxes 123 + digital assets loss 68 + other 1,086. Forecast zero.
A10: Change in working capital & other operating items | D10: 642 | E10: =-(BS!E7-BS!D7)-(BS!E8-BS!D8)-(BS!E9-BS!D9)+(BS!E16-BS!D16)+(BS!E17-BS!D17)+(BS!E18-BS!D18)+(BS!E20-BS!D20)-(BS!E13-BS!D13)-(BS!E12-BS!D12) -> 536.38605 | F10: =-(BS!F7-BS!E7)-(BS!F8-BS!E8)-(BS!F9-BS!E9)+(BS!F16-BS!E16)+(BS!F17-BS!E17)+(BS!F18-BS!E18)+(BS!F20-BS!E20)-(BS!F13-BS!E13)-(BS!F12-BS!E12) -> 707.0304 | G10: =-(BS!G7-BS!F7)-(BS!G8-BS!F8)-(BS!G9-BS!F9)+(BS!G16-BS!F16)+(BS!G17-BS!F17)+(BS!G18-BS!F18)+(BS!G20-BS!F20)-(BS!G13-BS!F13)-(BS!G12-BS!F12) -> 841.22836 | H10: =-(BS!H7-BS!G7)-(BS!H8-BS!G8)-(BS!H9-BS!G9)+(BS!H16-BS!G16)+(BS!H17-BS!G17)+(BS!H18-BS!G18)+(BS!H20-BS!G20)-(BS!H13-BS!G13)-(BS!H12-BS!G12) -> 843.5819 | I10: =-(BS!I7-BS!H7)-(BS!I8-BS!H8)-(BS!I9-BS!H9)+(BS!I16-BS!H16)+(BS!I17-BS!H17)+(BS!I18-BS!H18)+(BS!I20-BS!H20)-(BS!I13-BS!H13)-(BS!I12-BS!H12) -> 778.02325 | J10: FY25A: -554-673+2,083-214 (quarterly). Forecast = sum of balance-sheet movements (AR, inventory, prepaid, AP, accruals, deferred revenue, other LT).
A11: Net cash from operating activities | B11: 13256 | C11: 14923 | D11: =SUM(D6:D10) -> 14747 | E11: =SUM(E6:E10) -> 15080.373 | F11: =SUM(F6:F10) -> 18331.835 | G11: =SUM(G6:G10) -> 21270.806 | H11: =SUM(H6:H10) -> 23785.811 | I11: =SUM(I6:I10) -> 25955.758 | J11: FY25A ties to reported 14,747 (see Checks). FY23-24 as reported.
A13: Capital expenditures (incl. energy systems) | B13: -8899 | C13: -11342 | D13: -8527 | E13: =-Assumptions!E50*IS!E9 -> -20730.218 | F13: =-Assumptions!F50*IS!F9 -> -17551.869 | G13: =-Assumptions!G50*IS!G9 -> -14908.903 | H13: =-Assumptions!H50*IS!H9 -> -13447.643 | I13: =-Assumptions!I50*IS!I9 -> -12215.248 | J13: Tesla definition from Q1-25 (includes purchases of energy generation & storage systems), prior years restated.
A14: Net (purchases) / maturities of investments & other | D14: -6951 | E14: 0 | F14: 0 | G14: 0 | H14: 0 | I14: 0 | J14: FY25A: -37,109 purchases + 30,158 maturities. Forecast zero because BS cash line already includes investments.
A15: Net cash from investing activities | D15: =D13+D14 -> -15478 | E15: =E13+E14 -> -20730.218 | F15: =F13+F14 -> -17551.869 | G15: =G13+G14 -> -14908.903 | H15: =H13+H14 -> -13447.643 | I15: =I13+I14 -> -12215.248 | J15: FY25A ties to reported -15,478.
A17: Financing activities (debt, NCI, equity plan proceeds) | D17: 1139 | E17: =Schedules!E100 -> 305.03582 | F17: =Schedules!F100 -> 280.23534 | G17: =Schedules!G100 -> 166.00173 | H17: =Schedules!H100 -> 202.42547 | I17: =Schedules!I100 -> 121.63126 | J17: FY25A: -332-222+983+710 (quarterly). Forecast = net debt issuance from the debt schedule only.
A18: Effect of FX on cash | D18: 171 | E18: 0 | F18: 0 | G18: 0 | H18: 0 | I18: 0 | J18: FY25A: 40+111-17+37.
A19: Net change in cash | D19: =D11+D15+D17+D18 -> 579 | E19: =E11+E15+E17+E18 -> -5344.8101 | F19: =F11+F15+F17+F18 -> 1060.2015 | G19: =G11+G15+G17+G18 -> 6527.9051 | H19: =H11+H15+H17+H18 -> 10540.594 | I19: =I11+I15+I17+I18 -> 13862.142 | J19: FY25A = change in cash & restricted cash (579 reported). Forecast = change in cash & investments on the BS.
A21: Free cash flow (CFO + capex) | B21: =B11+B13 -> 4357 | C21: =C11+C13 -> 3581 | D21: =D11+D13 -> 6220 | E21: =E11+E13 -> -5649.8459 | F21: =F11+F13 -> 779.96618 | G21: =G11+G13 -> 6361.9034 | H21: =H11+H13 -> 10338.168 | I21: =I11+I13 -> 13740.51 | J21: Tesla's definition. Ties to reported 4,357 / 3,581 / 6,220.

Sheet DCF
A1: Tesla, Inc. - Discounted cash flow (unlevered)
A2: Linked to the three statements. End-of-year discounting from 31-Dec-2025 balance sheet date. SBC treated as a real cost (not added back).
A4: ($mm unless stated) | D4: FY2025A | E4: FY2026E | F4: FY2027E | G4: FY2028E | H4: FY2029E | I4: FY2030E | J4: Source / note
A5: Revenue | D5: =IS!D9 -> 94827 | E5: =IS!E9 -> 101123.02 | F5: =IS!F9 -> 109699.18 | G5: =IS!G9 -> 119271.22 | H5: =IS!H9 -> 128072.79 | I5: =IS!I9 -> 135724.98
A6: EBIT | D6: =IS!D21 -> 4355 | E6: =IS!E21 -> 5248.1043 | F6: =IS!F21 -> 6777.1525 | G6: =IS!G21 -> 8510.0572 | H6: =IS!H21 -> 10328.873 | I6: =IS!I21 -> 12036.395
A7: EBIT margin | D7: =D6/D5 -> 0.045925738 | E7: =E6/E5 -> 0.051898217 | F7: =F6/F5 -> 0.061779428 | G7: =G6/G5 -> 0.071350464 | H7: =H6/H5 -> 0.080648461 | I7: =I6/I5 -> 0.088682243
A8: Less: taxes on EBIT | E8: =-E6*Assumptions!E65 -> -1312.0261 | F8: =-F6*Assumptions!F65 -> -1694.2881 | G8: =-G6*Assumptions!G65 -> -2127.5143 | H8: =-H6*Assumptions!H65 -> -2582.2183 | I8: =-I6*Assumptions!I65 -> -3009.0988
A9: NOPAT | E9: =E6+E8 -> 3936.0782 | F9: =F6+F8 -> 5082.8643 | G9: =G6+G8 -> 6382.5429 | H9: =H6+H8 -> 7746.6549 | I9: =I6+I8 -> 9027.2964
A10: Plus: D&A | E10: =CF!E7 -> 6520.67 | F10: =CF!F7 -> 8367.9113 | G10: =CF!G7 -> 9561.8257 | H10: =CF!H7 -> 10256.946 | I10: =CF!I7 -> 10671.736
A11: Less: capital expenditures | E11: =CF!E13 -> -20730.218 | F11: =CF!F13 -> -17551.869 | G11: =CF!G13 -> -14908.903 | H11: =CF!H13 -> -13447.643 | I11: =CF!I13 -> -12215.248
A12: Plus / (less): change in working capital & other operating items | E12: =CF!E10 -> 536.38605 | F12: =CF!F10 -> 707.0304 | G12: =CF!G10 -> 841.22836 | H12: =CF!H10 -> 843.5819 | I12: =CF!I10 -> 778.02325 | J12: Sign convention: CF sheet movement (negative = cash outflow).
A13: Unlevered free cash flow (UFCF) | E13: =E9+E10+E11+E12 -> -9737.0842 | F13: =F9+F10+F11+F12 -> -3394.0625 | G13: =G9+G10+G11+G12 -> 1876.694 | H13: =H9+H10+H11+H12 -> 5399.5399 | I13: =I9+I10+I11+I12 -> 8261.8083 | J13: NOPAT + D&A - capex - change in working capital. SBC not added back (conservative, avoids ignoring dilution).
A15: Discount period (years) | E15: 1 | F15: 2 | G15: 3 | H15: 4 | I15: 5
A16: Discount factor | E16: =1/(1+$B$34)^E15 -> 0.88098355 | F16: =1/(1+$B$34)^F15 -> 0.77613202 | G16: =1/(1+$B$34)^G15 -> 0.68375954 | H16: =1/(1+$B$34)^H15 -> 0.6023809 | I16: =1/(1+$B$34)^I15 -> 0.53068767
A17: PV of UFCF | E17: =E13*E16 -> -8578.211 | F17: =F13*F16 -> -2634.2406 | G17: =G13*G16 -> 1283.2074 | H17: =H13*H16 -> 3252.5798 | I17: =I13*I16 -> 4384.4398
A19: Cost of capital (WACC)
A21: Risk-free rate | B21: =Assumptions!B70 -> 0.0524
A22: Equity beta | B22: =Assumptions!B72 -> 1.85
A23: Equity risk premium | B23: =Assumptions!B71 -> 0.045
A24: Cost of equity (CAPM) | B24: =B21+B22*B23 -> 0.13565 | J24: Cost of equity dominates: debt is <1% of capital at market values.
A25: Pre-tax cost of debt | B25: =Assumptions!B73 -> 0.055
A26: Tax rate (terminal year) | B26: =Assumptions!I65 -> 0.25
A27: After-tax cost of debt | B27: =B25*(1-B26) -> 0.04125
A28: Share price ($) | B28: =Assumptions!B74 -> 358.54
A29: Diluted shares (mm) | B29: =Assumptions!B75 -> 3950
A30: Market capitalisation ($mm) | B30: =B28*B29 -> 1416233
A31: Debt & finance leases ($mm, FY2025A) | B31: =BS!D19 -> 8376
A32: Equity weight E/(D+E) | B32: =B30/(B30+B31) -> 0.99412049
A33: Debt weight D/(D+E) | B33: =B31/(B30+B31) -> 0.005879508
A34: WACC | B34: =B32*B24+B33*B27 -> 0.13509497 | J34: A ~13-14% WACC reflects a 5.2% risk-free rate and a beta near 1.85.
A36: Terminal value & enterprise value
A37: Terminal growth rate | B37: =Assumptions!B76 -> 0.03
A38: Terminal-year UFCF (FY2030E) | B38: =I13 -> 8261.8083
A39: Terminal value at FY2030E (Gordon growth) | B39: =B38*(1+B37)/(B34-B37) -> 80971.165
A40: PV of terminal value | B40: =B39*I16 -> 42970.399
A41: Sum of PV of UFCF (FY2026E-30E) | B41: =SUM(E17:I17) -> -2292.2247
A42: Enterprise value | B42: =B40+B41 -> 40678.174
A43: Terminal value as % of EV | B43: =B40/B42 -> 1.0563502
A44: Implied terminal EV / EBITDA (FY2030E) | B44: =B39/IS!I38 -> 3.5657343 | J44: Sanity check on the perpetuity: a mature auto/energy business typically trades 6-12x EBITDA.
A45: Terminal-year capex / D&A | B45: =-I11/I10 -> 1.1446355 | J45: Should sit near 1.0-1.3x in steady state; much higher means terminal FCF is understated, much lower means it is overstated.
...

Sheet Checks
A1: Model integrity checks
A2: Differences should be zero. Reported figures are hard-coded inputs from Tesla filings; tolerance 0.5.
A4: Check ($mm) | B4: FY2023A | C4: FY2024A | D4: FY2025A | E4: FY2026E | F4: FY2027E | G4: FY2028E | H4: FY2029E | I4: FY2030E | J4: Source / note
A5: Reported figures (source)
A6: Reported total revenues | B6: 96773 | C6: 97690 | D6: 94827 | J6: Tesla Q4/FY2025 Update (8-K Ex. 99.1) - Financial Summary (annual)
A7: Reported gross profit | B7: 17660 | C7: 17450 | D7: 17094 | J7: Tesla Q4/FY2025 Update (8-K Ex. 99.1) - Financial Summary (annual)
A8: Reported income from operations | B8: 8891 | C8: 7076 | D8: 4355 | J8: Tesla Q4/FY2025 Update (8-K Ex. 99.1) - Financial Summary (annual)
A9: Reported net income to common stockholders (GAAP) | B9: 14997 | C9: 7091 | D9: 3794 | J9: Tesla Q4/FY2025 Update (8-K Ex. 99.1) - Financial Summary (annual)
A10: Reported operating cash flow | B10: 13256 | C10: 14923 | D10: 14747 | J10: Tesla Q4/FY2025 Update (8-K Ex. 99.1) - Financial Summary (annual)
A11: Reported free cash flow | B11: 4357 | C11: 3581 | D11: 6220 | J11: Tesla Q4/FY2025 Update (8-K Ex. 99.1) - Financial Summary (annual)
A12: Reported investing cash flow (FY2025) | D12: -15478 | J12: Sum of quarters, Q4/FY2025 Update p.30
A13: Reported net change in cash & restricted cash (FY2025) | D13: 579 | J13: Sum of quarters: 213-515+2,849-1,968
A14: Reported total assets | C14: 122070 | D14: 137806 | J14: Balance sheet, Q4/FY2025 Update p.29
A15: Reported total liabilities | C15: 48390 | D15: 54941 | J15: Balance sheet, Q4/FY2025 Update p.29
A17: Differences (model - reported)
A18: Total revenues | B18: =IS!B9-B6 -> 0 | C18: =IS!C9-C6 -> 0 | D18: =IS!D9-D6 -> 0
A19: Gross profit | B19: =IS!B15-B7 -> 0 | C19: =IS!C15-C7 -> 0 | D19: =IS!D15-D7 -> 0
A20: Operating income | B20: =IS!B21-B8 -> 0 | C20: =IS!C21-C8 -> 0 | D20: =IS!D21-D8 -> 0
A21: Net income to common | B21: =IS!B31-B9 -> 0 | C21: =IS!C31-C9 -> 0 | D21: =IS!D31-D9 -> 0
A22: Operating cash flow | B22: =CF!B11-B10 -> 0 | C22: =CF!C11-C10 -> 0 | D22: =CF!D11-D10 -> 0
A23: Free cash flow | B23: =CF!B21-B11 -> 0 | C23: =CF!C21-C11 -> 0 | D23: =CF!D21-D11 -> 0
A24: Investing cash flow (FY2025) | D24: =CF!D15-D12 -> 0
A25: Net change in cash (FY2025) | D25: =CF!D19-D13 -> 0
A26: Total assets | C26: =BS!C14-C14 -> 0 | D26: =BS!D14-D14 -> 0
A27: Total liabilities | C27: =BS!C21-C15 -> 0 | D27: =BS!D21-D15 -> 0
A28: Balance sheet balances (assets - liabilities & equity) | C28: =BS!C28 -> 0 | D28: =BS!D28 -> 0 | E28: =BS!E28 -> 0 | F28: =BS!F28 -> 0 | G28: =BS!G28 -> 0 | H28: =BS!H28 -> 0 | I28: =BS!I28 -> 0
A29: Forecast: change in BS cash - CF net change in cash | E29: =(BS!E6-BS!D6)-CF!E19 -> 0 | F29: =(BS!F6-BS!E6)-CF!F19 -> 0 | G29: =(BS!G6-BS!F6)-CF!G19 -> 0 | H29: =(BS!H6-BS!G6)-CF!H19 -> 0 | I29: =(BS!I6-BS!H6)-CF!I19 -> 0
A30: Sensitivity centre cell - DCF value per share | E30: =DCF!E63-DCF!B55 -> 0
A31: Debt tranches (FY2025A) - balance sheet debt | D31: =Schedules!D99-BS!D19 -> 0
A32: Debt schedule closing - balance sheet debt | E32: =Schedules!E99-BS!E19 -> 0 | F32: =Schedules!F99-BS!F19 -> 0 | G32: =Schedules!G99-BS!G19 -> 0 | H32: =Schedules!H99-BS!H19 -> 0 | I32: =Schedules!I99-BS!I19 -> 0
A33: Deferred revenue roll-forward closing - balance sheet | E33: =Schedules!E44-BS!E18 -> 0 | F33: =Schedules!F44-BS!F18 -> 0 | G33: =Schedules!G44-BS!G18 -> 0 | H33: =Schedules!H44-BS!H18 -> 0 | I33: =Schedules!I44-BS!I18 -> 0
A34: Deferred revenue opening FY2026E - FY2025A balance sheet | E34: =Schedules!E41-BS!D18 -> 0
A35: Segment build: auto + energy + services - total revenue | E35: =Schedules!E19+Schedules!E34+IS!E8-IS!E9 -> 0 | F35: =Schedules!F19+Schedules!F34+IS!F8-IS!F9 -> 0 | G35: =Schedules!G19+Schedules!G34+IS!G8-IS!G9 -> 0 | H35: =Schedules!H19+Schedules!H34+IS!H8-IS!H9 -> 0 | I35: =Schedules!I19+Schedules!I34+IS!I8-IS!I9 -> 0
A36: Debt mix shares sum to 100% | C36: =(Schedules!C57-1)*100 -> 0
A38: OVERALL STATUS | B38: =IF(SUMPRODUCT(ABS(B18:I36))<0.5,"ALL CHECKS PASS","CHECK ERRORS") -> ALL CHECKS PASS

Sheet Sources
A1: Sources & data log
A2: Every hard-coded historical number and market input in the model traces to one of these.
A4: Item | B4: Used for | C4: Source
A5: Tesla Q4 & FY2025 Update (8-K Ex. 99.1) | B5: FY2021-25 annual summary; Q4-24 to Q4-25 quarterly income statement, balance sheet, cash flow, non-GAAP reconciliations | C5: https://www.sec.gov/Archives/edgar/data/1318605/000162828026003837/exhibit991.htm
A6: Tesla Form 10-K, FY2025 | B6: Balance sheet detail (cash vs. short-term investments), shares outstanding, debt principal ($8.18bn) | C6: https://www.sec.gov/Archives/edgar/data/1318605/000162828026003952/tsla-20251231.htm
A7: FY2025 quarterly aggregation | B7: FY2025A income statement and cash flow lines are the sum of Q1-Q4 2025 reported quarters; totals tie to the 10-K/Update annual figures (see Checks) | C7: Same as row 1
A8: FY2023-24 lines | B8: Reported totals only (revenue by segment, gross profit, opex, EBIT, interest expense, tax, net income, D&A, SBC, CFO, capex). Segment COGS and detailed opex not sourced. | C8: Row 1, annual summary and reconciliation tables
A9: US 10-year Treasury yield 5.24% | B9: Risk-free rate (29-Sep-2026) | C9: https://tradingeconomics.com/united-states/government-bond-yield ; https://en.macromicro.me/series/354/10year-bond-yield
A10: TSLA share price $358.54 | B10: Market capitalisation, WACC weights, upside/downside (close 28-Sep-2026) | C10: https://finance.yahoo.com/quote/TSLA/history/
A11: TSLA beta 1.78-1.92 | B11: CAPM; 1.85 chosen | C11: https://www.tradingview.com/symbols/NASDAQ-TSLA/ ; https://www.cnbc.com/quotes/TSLA ; https://marketchameleon.com/Overview/TSLA
A12: Shares outstanding ~3.95bn | B12: Per-share value and market cap | C12: https://www.cnbc.com/quotes/TSLA ; https://www.google.com/finance/beta/quote/TSLA:NASDAQ
A13: 2026 capex guidance ">$20bn" | B13: FY2026E capex calibration | C13: https://quartr.com/events/tesla-inc-tsla-q4-2025_3ek6D0lv ; https://www.fool.com/earnings/call-transcripts/2026/01/28/tesla-tsla-q4-2025-earnings-call-transcript/
A14: Tesla Form 10-Q, Q1 2026 | B14: Debt by instrument at 31-Mar-2026 (used as the tranche mix), deferred revenue commentary | C14: https://www.sec.gov/Archives/edgar/data/1318605/000162828026026673/tsla-20260331.htm ; https://ir.tesla.com/_flysystem/s3/sec/000162828026026673/tsla-20260331-gen.pdf
A15: Analyst assumptions | B15: ERP 4.5%, terminal growth 3.0%, all forecast drivers on Assumptions sheet | C15: Author judgement - flagged blue on Assumptions; no company guidance implied beyond 2026 capex.
